$ valgrind --leak-check=yes --suppressions=util/valgrind-suppressions ./build/X86/gem5.debug \
        --stats-file=se-test-stats \
        --debug-flags=GarnetMulticast \
        ./configs/deprecated/example/se.py \
        --ruby \
        --network=garnet \
        --cpu-type=TimingSimpleCPU \
        --caches \
        --l2cache \
        --num-l2cache=16 \
        --num-cpus=16 \
        --num-dirs=16 \
        --topology=Mesh_XY \
        --mesh-rows=4 \
        --multicast \
        --cmd="./tests/test-progs/hello/bin/x86/linux/hello"
==34772== Memcheck, a memory error detector
==34772== Copyright (C) 2002-2017, and GNU GPL'd, by Julian Seward et al.
==34772== Using Valgrind-3.16.1 and LibVEX; rerun with -h for copyright info
==34772== Command: ./build/X86/gem5.debug --stats-file=se-test-stats --debug-flags=GarnetMulticast ./configs/deprecated/example/se.py --ruby --network=garnet --cpu-type=TimingSimpleCPU --caches --l2cache --num-l2cache=16 --num-cpus=16 --num-dirs=16 --topology=Mesh_XY --mesh-rows=4 --multicast --cmd=./tests/test-progs/hello/bin/x86/linux/hello
==34772==
gem5 Simulator System.  https://www.gem5.org
gem5 is copyrighted software; use the --copyright option for details.

gem5 version [DEVELOP-FOR-23.0]
gem5 compiled May 10 2023 16:57:08
gem5 started May 10 2023 17:08:54
gem5 executing on debian-dell-g5, pid 34772
command line: ./build/X86/gem5.debug --stats-file=se-test-stats --debug-flags=GarnetMulticast ./configs/deprecated/example/se.py --ruby --network=garnet --cpu-type=TimingSimpleCPU --caches --l2cache --num-l2cache=16 --num-cpus=16 --num-dirs=16 --topology=Mesh_XY --mesh-rows=4 --multicast --cmd=./tests/test-progs/hello/bin/x86/linux/hello

warn: The `get_runtime_isa` function is deprecated. Please migrate away from using this function.
warn: The se.py script is deprecated. It will be removed in future releases of  gem5.
warn: The `get_runtime_isa` function is deprecated. Please migrate away from using this function.
warn: The `get_runtime_isa` function is deprecated. Please migrate away from using this function.
warn: The `get_runtime_isa` function is deprecated. Please migrate away from using this function.
warn: The `get_runtime_isa` function is deprecated. Please migrate away from using this function.
warn: The `get_runtime_isa` function is deprecated. Please migrate away from using this function.
warn: The `get_runtime_isa` function is deprecated. Please migrate away from using this function.
warn: The `get_runtime_isa` function is deprecated. Please migrate away from using this function.
warn: The `get_runtime_isa` function is deprecated. Please migrate away from using this function.
warn: The `get_runtime_isa` function is deprecated. Please migrate away from using this function.
warn: The `get_runtime_isa` function is deprecated. Please migrate away from using this function.
warn: The `get_runtime_isa` function is deprecated. Please migrate away from using this function.
warn: The `get_runtime_isa` function is deprecated. Please migrate away from using this function.
warn: The `get_runtime_isa` function is deprecated. Please migrate away from using this function.
warn: The `get_runtime_isa` function is deprecated. Please migrate away from using this function.
warn: The `get_runtime_isa` function is deprecated. Please migrate away from using this function.
warn: The `get_runtime_isa` function is deprecated. Please migrate away from using this function.
Global frequency set at 1000000000000 ticks per second
warn: No dot file generated. Please install pydot to generate the dot file and pdf.
build/X86/mem/dram_interface.cc:690: warn: DRAM device capacity (8192 Mbytes) does not match the address range assigned (32 Mbytes)
build/X86/mem/dram_interface.cc:690: warn: DRAM device capacity (8192 Mbytes) does not match the address range assigned (32 Mbytes)
build/X86/mem/dram_interface.cc:690: warn: DRAM device capacity (8192 Mbytes) does not match the address range assigned (32 Mbytes)
build/X86/mem/dram_interface.cc:690: warn: DRAM device capacity (8192 Mbytes) does not match the address range assigned (32 Mbytes)
build/X86/mem/dram_interface.cc:690: warn: DRAM device capacity (8192 Mbytes) does not match the address range assigned (32 Mbytes)
build/X86/mem/dram_interface.cc:690: warn: DRAM device capacity (8192 Mbytes) does not match the address range assigned (32 Mbytes)
build/X86/mem/dram_interface.cc:690: warn: DRAM device capacity (8192 Mbytes) does not match the address range assigned (32 Mbytes)
build/X86/mem/dram_interface.cc:690: warn: DRAM device capacity (8192 Mbytes) does not match the address range assigned (32 Mbytes)
build/X86/mem/dram_interface.cc:690: warn: DRAM device capacity (8192 Mbytes) does not match the address range assigned (32 Mbytes)
build/X86/mem/dram_interface.cc:690: warn: DRAM device capacity (8192 Mbytes) does not match the address range assigned (32 Mbytes)
build/X86/mem/dram_interface.cc:690: warn: DRAM device capacity (8192 Mbytes) does not match the address range assigned (32 Mbytes)
build/X86/mem/dram_interface.cc:690: warn: DRAM device capacity (8192 Mbytes) does not match the address range assigned (32 Mbytes)
build/X86/mem/dram_interface.cc:690: warn: DRAM device capacity (8192 Mbytes) does not match the address range assigned (32 Mbytes)
build/X86/mem/dram_interface.cc:690: warn: DRAM device capacity (8192 Mbytes) does not match the address range assigned (32 Mbytes)
build/X86/mem/dram_interface.cc:690: warn: DRAM device capacity (8192 Mbytes) does not match the address range assigned (32 Mbytes)
build/X86/mem/dram_interface.cc:690: warn: DRAM device capacity (8192 Mbytes) does not match the address range assigned (32 Mbytes)
==34772== Warning: set address range perms: large range [0xa1f6000, 0x2a1f6000) (defined)
build/X86/base/statistics.hh:279: warn: One of the stats is a legacy stat. Legacy stat is a stat that does not belong to any statistics::Group. Legacy stat is deprecated.
build/X86/base/statistics.hh:279: warn: One of the stats is a legacy stat. Legacy stat is a stat that does not belong to any statistics::Group. Legacy stat is deprecated.
build/X86/base/statistics.hh:279: warn: One of the stats is a legacy stat. Legacy stat is a stat that does not belong to any statistics::Group. Legacy stat is deprecated.
build/X86/base/statistics.hh:279: warn: One of the stats is a legacy stat. Legacy stat is a stat that does not belong to any statistics::Group. Legacy stat is deprecated.
      0: system.ruby.network: Multicast enabled.
build/X86/mem/ruby/network/garnet/GarnetNetwork.cc:115: info: Garnet version 3.0
system.remote_gdb: Listening for connections on port 7000
**** REAL SIMULATION ****
build/X86/sim/simulate.cc:194: info: Entering event queue @ 0.  Starting simulation...
==34772== Invalid write of size 4
==34772==    at 0x1AC9137: gem5::ruby::garnet::NetworkInterface::flitisizeMessage(std::shared_ptr<gem5::ruby::Message>, int) (NetworkInterface.cc:426)
==34772==    by 0x1AC7BFC: gem5::ruby::garnet::NetworkInterface::wakeup() (NetworkInterface.cc:214)
==34772==    by 0x190FA48: gem5::ruby::Consumer::processCurrentEvent() (Consumer.cc:94)
==34772==    by 0x190F5D8: gem5::ruby::Consumer::Consumer(gem5::ClockedObject*, signed char)::{lambda()#1}::operator()() const (Consumer.cc:50)
==34772==    by 0x190FDA9: void std::__invoke_impl<void, gem5::ruby::Consumer::Consumer(gem5::ClockedObject*, signed char)::{lambda()#1}&>(std::__invoke_other, gem5::ruby::Consumer::Consumer(gem5::ClockedObject*, signed char)::{lambda()#1}&) (invoke.h:60)
==34772==    by 0x190FC99: std::enable_if<is_invocable_r_v<void, gem5::ruby::Consumer::Consumer(gem5::ClockedObject*, signed char)::{lambda()#1}&>, std::enable_if>::type std::__invoke_r<void, gem5::ruby::Consumer::Consumer(gem5::ClockedObject*, signed char)::{lambda()#1}&>(void&&, (gem5::ruby::Consumer::Consumer(gem5::ClockedObject*, signed char)::{lambda()#1}&)...) (invoke.h:110)
==34772==    by 0x190FB8B: std::_Function_handler<void (), gem5::ruby::Consumer::Consumer(gem5::ClockedObject*, signed char)::{lambda()#1}>::_M_invoke(std::_Any_data const&) (std_function.h:291)
==34772==    by 0x372991: std::function<void ()>::operator()() const (std_function.h:622)
==34772==    by 0x371357: gem5::EventFunctionWrapper::process() (eventq.hh:1162)
==34772==    by 0xEA2788: gem5::EventQueue::serviceOne() (eventq.cc:249)
==34772==    by 0xECBD09: gem5::doSimLoop(gem5::EventQueue*) (simulate.cc:323)
==34772==    by 0xECB853: gem5::simulate(unsigned long) (simulate.cc:229)
==34772==  Address 0x0 is not stack'd, malloc'd or (recently) free'd
==34772==
gem5 has encountered a segmentation fault!

--- BEGIN LIBC BACKTRACE ---
./build/X86/gem5.debug(+0xd877c4)[0xe8f7c4]
./build/X86/gem5.debug(+0xdaa661)[0xeb2661]
/lib/x86_64-linux-gnu/libpthread.so.0(+0x13140)[0x4e08140]
./build/X86/gem5.debug(+0x19c1137)[0x1ac9137]
./build/X86/gem5.debug(+0x19bfbfd)[0x1ac7bfd]
./build/X86/gem5.debug(+0x1807a49)[0x190fa49]
./build/X86/gem5.debug(+0x18075d9)[0x190f5d9]
./build/X86/gem5.debug(+0x1807daa)[0x190fdaa]
./build/X86/gem5.debug(+0x1807c9a)[0x190fc9a]
./build/X86/gem5.debug(+0x1807b8c)[0x190fb8c]
./build/X86/gem5.debug(+0x26a992)[0x372992]
./build/X86/gem5.debug(+0x269358)[0x371358]
./build/X86/gem5.debug(+0xd9a789)[0xea2789]
./build/X86/gem5.debug(+0xdc3d0a)[0xecbd0a]
./build/X86/gem5.debug(+0xdc3854)[0xecb854]
./build/X86/gem5.debug(+0x1320670)[0x1428670]
./build/X86/gem5.debug(+0x131efe3)[0x1426fe3]
./build/X86/gem5.debug(+0x131b76a)[0x142376a]
./build/X86/gem5.debug(+0x131b7bd)[0x14237bd]
./build/X86/gem5.debug(+0x226654)[0x32e654]
/lib/x86_64-linux-gnu/libpython3.9.so.1.0(+0x10cc93)[0x4976c93]
/lib/x86_64-linux-gnu/libpython3.9.so.1.0(_PyObject_Call+0x5c)[0x493331c]
/lib/x86_64-linux-gnu/libpython3.9.so.1.0(_PyEval_EvalFrameDefault+0x4a59)[0x48de719]
/lib/x86_64-linux-gnu/libpython3.9.so.1.0(+0x1a4ddc)[0x4a0eddc]
/lib/x86_64-linux-gnu/libpython3.9.so.1.0(_PyFunction_Vectorcall+0x9d)[0x492bc7d]
/lib/x86_64-linux-gnu/libpython3.9.so.1.0(_PyEval_EvalFrameDefault+0x78c5)[0x48e1585]
/lib/x86_64-linux-gnu/libpython3.9.so.1.0(+0x6f033)[0x48d9033]
/lib/x86_64-linux-gnu/libpython3.9.so.1.0(_PyEval_EvalFrameDefault+0x6456)[0x48e0116]
/lib/x86_64-linux-gnu/libpython3.9.so.1.0(+0x1a4ddc)[0x4a0eddc]
/lib/x86_64-linux-gnu/libpython3.9.so.1.0(_PyFunction_Vectorcall+0x9d)[0x492bc7d]
/lib/x86_64-linux-gnu/libpython3.9.so.1.0(_PyEval_EvalFrameDefault+0x78c5)[0x48e1585]
/lib/x86_64-linux-gnu/libpython3.9.so.1.0(+0x1a4ddc)[0x4a0eddc]
--- END LIBC BACKTRACE ---
==34772==
==34772== Process terminating with default action of signal 11 (SIGSEGV)
==34772==    at 0x4E04F44: pthread_kill (pthread_kill.c:57)
==34772==    by 0xEB24F0: gem5::raiseFatalSignal(int) (init_signals.cc:106)
==34772==    by 0xEB266A: gem5::segvHandler(int) (init_signals.cc:167)
==34772==    by 0x4E0813F: ??? (in /usr/lib/x86_64-linux-gnu/libpthread-2.31.so)
==34772==    by 0x1AC9136: gem5::ruby::garnet::NetworkInterface::flitisizeMessage(std::shared_ptr<gem5::ruby::Message>, int) (NetworkInterface.cc:426)
==34772==
==34772== HEAP SUMMARY:
==34772==     in use at exit: 246,319,749 bytes in 3,151,903 blocks
==34772==   total heap usage: 7,087,495 allocs, 3,935,592 frees, 489,028,999 bytes allocated
==34772==
==34772== 520 bytes in 1 blocks are possibly lost in loss record 32,084 of 35,156
==34772==    at 0x483877F: malloc (vg_replace_malloc.c:307)
==34772==    by 0x49809C7: ??? (in /usr/lib/x86_64-linux-gnu/libpython3.9.so.1.0)
==34772==    by 0x4A72244: _PyObject_GC_Malloc (in /usr/lib/x86_64-linux-gnu/libpython3.9.so.1.0)
==34772==    by 0x4A72567: _PyObject_GC_NewVar (in /usr/lib/x86_64-linux-gnu/libpython3.9.so.1.0)
==34772==    by 0x48E3750: ??? (in /usr/lib/x86_64-linux-gnu/libpython3.9.so.1.0)
==34772==    by 0x48D8FF0: ??? (in /usr/lib/x86_64-linux-gnu/libpython3.9.so.1.0)
==34772==    by 0x4932F22: _PyObject_FastCallDictTstate (in /usr/lib/x86_64-linux-gnu/libpython3.9.so.1.0)
==34772==    by 0x493313F: _PyObject_Call_Prepend (in /usr/lib/x86_64-linux-gnu/libpython3.9.so.1.0)
==34772==    by 0x49996F1: ??? (in /usr/lib/x86_64-linux-gnu/libpython3.9.so.1.0)
==34772==    by 0x498E939: ??? (in /usr/lib/x86_64-linux-gnu/libpython3.9.so.1.0)
==34772==    by 0x4930A4F: _PyObject_MakeTpCall (in /usr/lib/x86_64-linux-gnu/libpython3.9.so.1.0)
==34772==    by 0x48E0F07: _PyEval_EvalFrameDefault (in /usr/lib/x86_64-linux-gnu/libpython3.9.so.1.0)
==34772==
==34772== 520 bytes in 1 blocks are possibly lost in loss record 32,085 of 35,156
==34772==    at 0x483877F: malloc (vg_replace_malloc.c:307)
==34772==    by 0x49809C7: ??? (in /usr/lib/x86_64-linux-gnu/libpython3.9.so.1.0)
==34772==    by 0x4A72244: _PyObject_GC_Malloc (in /usr/lib/x86_64-linux-gnu/libpython3.9.so.1.0)
==34772==    by 0x4A72567: _PyObject_GC_NewVar (in /usr/lib/x86_64-linux-gnu/libpython3.9.so.1.0)
==34772==    by 0x48E3750: ??? (in /usr/lib/x86_64-linux-gnu/libpython3.9.so.1.0)
==34772==    by 0x4A0E565: ??? (in /usr/lib/x86_64-linux-gnu/libpython3.9.so.1.0)
==34772==    by 0x492BC7C: _PyFunction_Vectorcall (in /usr/lib/x86_64-linux-gnu/libpython3.9.so.1.0)
==34772==    by 0x48DFC4C: _PyEval_EvalFrameDefault (in /usr/lib/x86_64-linux-gnu/libpython3.9.so.1.0)
==34772==    by 0x48D9032: ??? (in /usr/lib/x86_64-linux-gnu/libpython3.9.so.1.0)
==34772==    by 0x48E14B6: _PyEval_EvalFrameDefault (in /usr/lib/x86_64-linux-gnu/libpython3.9.so.1.0)
==34772==    by 0x4A0EDDB: ??? (in /usr/lib/x86_64-linux-gnu/libpython3.9.so.1.0)
==34772==    by 0x492BC7C: _PyFunction_Vectorcall (in /usr/lib/x86_64-linux-gnu/libpython3.9.so.1.0)
==34772==
==34772== 520 bytes in 1 blocks are possibly lost in loss record 32,086 of 35,156
==34772==    at 0x483877F: malloc (vg_replace_malloc.c:307)
==34772==    by 0x49809C7: ??? (in /usr/lib/x86_64-linux-gnu/libpython3.9.so.1.0)
==34772==    by 0x4A72244: _PyObject_GC_Malloc (in /usr/lib/x86_64-linux-gnu/libpython3.9.so.1.0)
==34772==    by 0x4A72567: _PyObject_GC_NewVar (in /usr/lib/x86_64-linux-gnu/libpython3.9.so.1.0)
==34772==    by 0x48E3750: ??? (in /usr/lib/x86_64-linux-gnu/libpython3.9.so.1.0)
==34772==    by 0x4A0E565: ??? (in /usr/lib/x86_64-linux-gnu/libpython3.9.so.1.0)
==34772==    by 0x492BC7C: _PyFunction_Vectorcall (in /usr/lib/x86_64-linux-gnu/libpython3.9.so.1.0)
==34772==    by 0x48E0115: _PyEval_EvalFrameDefault (in /usr/lib/x86_64-linux-gnu/libpython3.9.so.1.0)
==34772==    by 0x48D9032: ??? (in /usr/lib/x86_64-linux-gnu/libpython3.9.so.1.0)
==34772==    by 0x48E1584: _PyEval_EvalFrameDefault (in /usr/lib/x86_64-linux-gnu/libpython3.9.so.1.0)
==34772==    by 0x48D9032: ??? (in /usr/lib/x86_64-linux-gnu/libpython3.9.so.1.0)
==34772==    by 0x493A3D2: ??? (in /usr/lib/x86_64-linux-gnu/libpython3.9.so.1.0)
==34772==
==34772== 520 bytes in 1 blocks are possibly lost in loss record 32,087 of 35,156
==34772==    at 0x483877F: malloc (vg_replace_malloc.c:307)
==34772==    by 0x49809C7: ??? (in /usr/lib/x86_64-linux-gnu/libpython3.9.so.1.0)
==34772==    by 0x4A72244: _PyObject_GC_Malloc (in /usr/lib/x86_64-linux-gnu/libpython3.9.so.1.0)
==34772==    by 0x4A72567: _PyObject_GC_NewVar (in /usr/lib/x86_64-linux-gnu/libpython3.9.so.1.0)
==34772==    by 0x48E3750: ??? (in /usr/lib/x86_64-linux-gnu/libpython3.9.so.1.0)
==34772==    by 0x4A0E565: ??? (in /usr/lib/x86_64-linux-gnu/libpython3.9.so.1.0)
==34772==    by 0x492BC7C: _PyFunction_Vectorcall (in /usr/lib/x86_64-linux-gnu/libpython3.9.so.1.0)
==34772==    by 0x4932F9D: _PyObject_FastCallDictTstate (in /usr/lib/x86_64-linux-gnu/libpython3.9.so.1.0)
==34772==    by 0x493313F: _PyObject_Call_Prepend (in /usr/lib/x86_64-linux-gnu/libpython3.9.so.1.0)
==34772==    by 0x4998F56: ??? (in /usr/lib/x86_64-linux-gnu/libpython3.9.so.1.0)
==34772==    by 0x498E8F5: ??? (in /usr/lib/x86_64-linux-gnu/libpython3.9.so.1.0)
==34772==    by 0x4930A4F: _PyObject_MakeTpCall (in /usr/lib/x86_64-linux-gnu/libpython3.9.so.1.0)
==34772==
==34772== 520 bytes in 1 blocks are possibly lost in loss record 32,088 of 35,156
==34772==    at 0x483877F: malloc (vg_replace_malloc.c:307)
==34772==    by 0x49809C7: ??? (in /usr/lib/x86_64-linux-gnu/libpython3.9.so.1.0)
==34772==    by 0x4A72244: _PyObject_GC_Malloc (in /usr/lib/x86_64-linux-gnu/libpython3.9.so.1.0)
==34772==    by 0x4A72567: _PyObject_GC_NewVar (in /usr/lib/x86_64-linux-gnu/libpython3.9.so.1.0)
==34772==    by 0x48E3750: ??? (in /usr/lib/x86_64-linux-gnu/libpython3.9.so.1.0)
==34772==    by 0x48D8FF0: ??? (in /usr/lib/x86_64-linux-gnu/libpython3.9.so.1.0)
==34772==    by 0x48E1584: _PyEval_EvalFrameDefault (in /usr/lib/x86_64-linux-gnu/libpython3.9.so.1.0)
==34772==    by 0x4A0EDDB: ??? (in /usr/lib/x86_64-linux-gnu/libpython3.9.so.1.0)
==34772==    by 0x492BC7C: _PyFunction_Vectorcall (in /usr/lib/x86_64-linux-gnu/libpython3.9.so.1.0)
==34772==    by 0x48E0115: _PyEval_EvalFrameDefault (in /usr/lib/x86_64-linux-gnu/libpython3.9.so.1.0)
==34772==    by 0x48D9032: ??? (in /usr/lib/x86_64-linux-gnu/libpython3.9.so.1.0)
==34772==    by 0x48E0115: _PyEval_EvalFrameDefault (in /usr/lib/x86_64-linux-gnu/libpython3.9.so.1.0)
==34772==
==34772== 520 bytes in 1 blocks are possibly lost in loss record 32,089 of 35,156
==34772==    at 0x483877F: malloc (vg_replace_malloc.c:307)
==34772==    by 0x49809C7: ??? (in /usr/lib/x86_64-linux-gnu/libpython3.9.so.1.0)
==34772==    by 0x4980ABF: ??? (in /usr/lib/x86_64-linux-gnu/libpython3.9.so.1.0)
==34772==    by 0x4A6E0D4: _PyObject_GC_Resize (in /usr/lib/x86_64-linux-gnu/libpython3.9.so.1.0)
==34772==    by 0x48E3568: ??? (in /usr/lib/x86_64-linux-gnu/libpython3.9.so.1.0)
==34772==    by 0x48D8FF0: ??? (in /usr/lib/x86_64-linux-gnu/libpython3.9.so.1.0)
==34772==    by 0x48E0115: _PyEval_EvalFrameDefault (in /usr/lib/x86_64-linux-gnu/libpython3.9.so.1.0)
==34772==    by 0x48D9032: ??? (in /usr/lib/x86_64-linux-gnu/libpython3.9.so.1.0)
==34772==    by 0x4932723: ??? (in /usr/lib/x86_64-linux-gnu/libpython3.9.so.1.0)
==34772==    by 0x4932A8A: _PyObject_CallMethodIdObjArgs (in /usr/lib/x86_64-linux-gnu/libpython3.9.so.1.0)
==34772==    by 0x4A34D3B: PyImport_ImportModuleLevelObject (in /usr/lib/x86_64-linux-gnu/libpython3.9.so.1.0)
==34772==    by 0x4A0B009: ??? (in /usr/lib/x86_64-linux-gnu/libpython3.9.so.1.0)
==34772==
==34772== 520 bytes in 1 blocks are possibly lost in loss record 32,090 of 35,156
==34772==    at 0x483877F: malloc (vg_replace_malloc.c:307)
==34772==    by 0x49809C7: ??? (in /usr/lib/x86_64-linux-gnu/libpython3.9.so.1.0)
==34772==    by 0x4980ABF: ??? (in /usr/lib/x86_64-linux-gnu/libpython3.9.so.1.0)
==34772==    by 0x4A6E0D4: _PyObject_GC_Resize (in /usr/lib/x86_64-linux-gnu/libpython3.9.so.1.0)
==34772==    by 0x48E3568: ??? (in /usr/lib/x86_64-linux-gnu/libpython3.9.so.1.0)
==34772==    by 0x4A0E565: ??? (in /usr/lib/x86_64-linux-gnu/libpython3.9.so.1.0)
==34772==    by 0x492BC7C: _PyFunction_Vectorcall (in /usr/lib/x86_64-linux-gnu/libpython3.9.so.1.0)
==34772==    by 0x48E1584: _PyEval_EvalFrameDefault (in /usr/lib/x86_64-linux-gnu/libpython3.9.so.1.0)
==34772==    by 0x4A0EDDB: ??? (in /usr/lib/x86_64-linux-gnu/libpython3.9.so.1.0)
==34772==    by 0x4A0F12D: _PyEval_EvalCodeWithName (in /usr/lib/x86_64-linux-gnu/libpython3.9.so.1.0)
==34772==    by 0x4A0F17D: PyEval_EvalCodeEx (in /usr/lib/x86_64-linux-gnu/libpython3.9.so.1.0)
==34772==    by 0x4A0A72A: PyEval_EvalCode (in /usr/lib/x86_64-linux-gnu/libpython3.9.so.1.0)
==34772==
==34772== 520 bytes in 1 blocks are possibly lost in loss record 32,091 of 35,156
==34772==    at 0x483877F: malloc (vg_replace_malloc.c:307)
==34772==    by 0x49809C7: ??? (in /usr/lib/x86_64-linux-gnu/libpython3.9.so.1.0)
==34772==    by 0x4A72244: _PyObject_GC_Malloc (in /usr/lib/x86_64-linux-gnu/libpython3.9.so.1.0)
==34772==    by 0x4A72567: _PyObject_GC_NewVar (in /usr/lib/x86_64-linux-gnu/libpython3.9.so.1.0)
==34772==    by 0x48E3750: ??? (in /usr/lib/x86_64-linux-gnu/libpython3.9.so.1.0)
==34772==    by 0x48D8FF0: ??? (in /usr/lib/x86_64-linux-gnu/libpython3.9.so.1.0)
==34772==    by 0x48E1584: _PyEval_EvalFrameDefault (in /usr/lib/x86_64-linux-gnu/libpython3.9.so.1.0)
==34772==    by 0x4A0EDDB: ??? (in /usr/lib/x86_64-linux-gnu/libpython3.9.so.1.0)
==34772==    by 0x492BC7C: _PyFunction_Vectorcall (in /usr/lib/x86_64-linux-gnu/libpython3.9.so.1.0)
==34772==    by 0x4932F22: _PyObject_FastCallDictTstate (in /usr/lib/x86_64-linux-gnu/libpython3.9.so.1.0)
==34772==    by 0x493313F: _PyObject_Call_Prepend (in /usr/lib/x86_64-linux-gnu/libpython3.9.so.1.0)
==34772==    by 0x4999608: ??? (in /usr/lib/x86_64-linux-gnu/libpython3.9.so.1.0)
==34772==
==34772== 520 bytes in 1 blocks are possibly lost in loss record 32,092 of 35,156
==34772==    at 0x483877F: malloc (vg_replace_malloc.c:307)
==34772==    by 0x49809C7: ??? (in /usr/lib/x86_64-linux-gnu/libpython3.9.so.1.0)
==34772==    by 0x4A72244: _PyObject_GC_Malloc (in /usr/lib/x86_64-linux-gnu/libpython3.9.so.1.0)
==34772==    by 0x4A72567: _PyObject_GC_NewVar (in /usr/lib/x86_64-linux-gnu/libpython3.9.so.1.0)
==34772==    by 0x48E3750: ??? (in /usr/lib/x86_64-linux-gnu/libpython3.9.so.1.0)
==34772==    by 0x4A0E565: ??? (in /usr/lib/x86_64-linux-gnu/libpython3.9.so.1.0)
==34772==    by 0x492BC7C: _PyFunction_Vectorcall (in /usr/lib/x86_64-linux-gnu/libpython3.9.so.1.0)
==34772==    by 0x48E0115: _PyEval_EvalFrameDefault (in /usr/lib/x86_64-linux-gnu/libpython3.9.so.1.0)
==34772==    by 0x4A0EDDB: ??? (in /usr/lib/x86_64-linux-gnu/libpython3.9.so.1.0)
==34772==    by 0x492BC7C: _PyFunction_Vectorcall (in /usr/lib/x86_64-linux-gnu/libpython3.9.so.1.0)
==34772==    by 0x48E0115: _PyEval_EvalFrameDefault (in /usr/lib/x86_64-linux-gnu/libpython3.9.so.1.0)
==34772==    by 0x4A0EDDB: ??? (in /usr/lib/x86_64-linux-gnu/libpython3.9.so.1.0)
==34772==
==34772== 520 bytes in 1 blocks are possibly lost in loss record 32,093 of 35,156
==34772==    at 0x483877F: malloc (vg_replace_malloc.c:307)
==34772==    by 0x49809C7: ??? (in /usr/lib/x86_64-linux-gnu/libpython3.9.so.1.0)
==34772==    by 0x4A72244: _PyObject_GC_Malloc (in /usr/lib/x86_64-linux-gnu/libpython3.9.so.1.0)
==34772==    by 0x4A72567: _PyObject_GC_NewVar (in /usr/lib/x86_64-linux-gnu/libpython3.9.so.1.0)
==34772==    by 0x48E3750: ??? (in /usr/lib/x86_64-linux-gnu/libpython3.9.so.1.0)
==34772==    by 0x48D8FF0: ??? (in /usr/lib/x86_64-linux-gnu/libpython3.9.so.1.0)
==34772==    by 0x48E0115: _PyEval_EvalFrameDefault (in /usr/lib/x86_64-linux-gnu/libpython3.9.so.1.0)
==34772==    by 0x48D9032: ??? (in /usr/lib/x86_64-linux-gnu/libpython3.9.so.1.0)
==34772==    by 0x4932F22: _PyObject_FastCallDictTstate (in /usr/lib/x86_64-linux-gnu/libpython3.9.so.1.0)
==34772==    by 0x493313F: _PyObject_Call_Prepend (in /usr/lib/x86_64-linux-gnu/libpython3.9.so.1.0)
==34772==    by 0x49996F1: ??? (in /usr/lib/x86_64-linux-gnu/libpython3.9.so.1.0)
==34772==    by 0x498E939: ??? (in /usr/lib/x86_64-linux-gnu/libpython3.9.so.1.0)
==34772==
==34772== 520 bytes in 1 blocks are possibly lost in loss record 32,094 of 35,156
==34772==    at 0x483877F: malloc (vg_replace_malloc.c:307)
==34772==    by 0x49809C7: ??? (in /usr/lib/x86_64-linux-gnu/libpython3.9.so.1.0)
==34772==    by 0x4980ABF: ??? (in /usr/lib/x86_64-linux-gnu/libpython3.9.so.1.0)
==34772==    by 0x4A6E0D4: _PyObject_GC_Resize (in /usr/lib/x86_64-linux-gnu/libpython3.9.so.1.0)
==34772==    by 0x48E3568: ??? (in /usr/lib/x86_64-linux-gnu/libpython3.9.so.1.0)
==34772==    by 0x4A0E565: ??? (in /usr/lib/x86_64-linux-gnu/libpython3.9.so.1.0)
==34772==    by 0x492BC7C: _PyFunction_Vectorcall (in /usr/lib/x86_64-linux-gnu/libpython3.9.so.1.0)
==34772==    by 0x4932F9D: _PyObject_FastCallDictTstate (in /usr/lib/x86_64-linux-gnu/libpython3.9.so.1.0)
==34772==    by 0x493313F: _PyObject_Call_Prepend (in /usr/lib/x86_64-linux-gnu/libpython3.9.so.1.0)
==34772==    by 0x49996F1: ??? (in /usr/lib/x86_64-linux-gnu/libpython3.9.so.1.0)
==34772==    by 0x498E939: ??? (in /usr/lib/x86_64-linux-gnu/libpython3.9.so.1.0)
==34772==    by 0x493331B: _PyObject_Call (in /usr/lib/x86_64-linux-gnu/libpython3.9.so.1.0)
==34772==
==34772== 520 bytes in 1 blocks are possibly lost in loss record 32,095 of 35,156
==34772==    at 0x483877F: malloc (vg_replace_malloc.c:307)
==34772==    by 0x49809C7: ??? (in /usr/lib/x86_64-linux-gnu/libpython3.9.so.1.0)
==34772==    by 0x4A72244: _PyObject_GC_Malloc (in /usr/lib/x86_64-linux-gnu/libpython3.9.so.1.0)
==34772==    by 0x4A72567: _PyObject_GC_NewVar (in /usr/lib/x86_64-linux-gnu/libpython3.9.so.1.0)
==34772==    by 0x48E3750: ??? (in /usr/lib/x86_64-linux-gnu/libpython3.9.so.1.0)
==34772==    by 0x4A0E565: ??? (in /usr/lib/x86_64-linux-gnu/libpython3.9.so.1.0)
==34772==    by 0x492BC7C: _PyFunction_Vectorcall (in /usr/lib/x86_64-linux-gnu/libpython3.9.so.1.0)
==34772==    by 0x48E14B6: _PyEval_EvalFrameDefault (in /usr/lib/x86_64-linux-gnu/libpython3.9.so.1.0)
==34772==    by 0x48D9032: ??? (in /usr/lib/x86_64-linux-gnu/libpython3.9.so.1.0)
==34772==    by 0x4933727: ??? (in /usr/lib/x86_64-linux-gnu/libpython3.9.so.1.0)
==34772==    by 0x48E1584: _PyEval_EvalFrameDefault (in /usr/lib/x86_64-linux-gnu/libpython3.9.so.1.0)
==34772==    by 0x48D9032: ??? (in /usr/lib/x86_64-linux-gnu/libpython3.9.so.1.0)
==34772==
==34772== 520 bytes in 1 blocks are possibly lost in loss record 32,096 of 35,156
==34772==    at 0x483877F: malloc (vg_replace_malloc.c:307)
==34772==    by 0x49809C7: ??? (in /usr/lib/x86_64-linux-gnu/libpython3.9.so.1.0)
==34772==    by 0x4A72244: _PyObject_GC_Malloc (in /usr/lib/x86_64-linux-gnu/libpython3.9.so.1.0)
==34772==    by 0x4A72567: _PyObject_GC_NewVar (in /usr/lib/x86_64-linux-gnu/libpython3.9.so.1.0)
==34772==    by 0x48E3750: ??? (in /usr/lib/x86_64-linux-gnu/libpython3.9.so.1.0)
==34772==    by 0x4A0E565: ??? (in /usr/lib/x86_64-linux-gnu/libpython3.9.so.1.0)
==34772==    by 0x492BC7C: _PyFunction_Vectorcall (in /usr/lib/x86_64-linux-gnu/libpython3.9.so.1.0)
==34772==    by 0x48E1584: _PyEval_EvalFrameDefault (in /usr/lib/x86_64-linux-gnu/libpython3.9.so.1.0)
==34772==    by 0x4A0EDDB: ??? (in /usr/lib/x86_64-linux-gnu/libpython3.9.so.1.0)
==34772==    by 0x492BC7C: _PyFunction_Vectorcall (in /usr/lib/x86_64-linux-gnu/libpython3.9.so.1.0)
==34772==    by 0x48E1584: _PyEval_EvalFrameDefault (in /usr/lib/x86_64-linux-gnu/libpython3.9.so.1.0)
==34772==    by 0x4A0EDDB: ??? (in /usr/lib/x86_64-linux-gnu/libpython3.9.so.1.0)
==34772==
==34772== 528 bytes in 1 blocks are possibly lost in loss record 32,106 of 35,156
==34772==    at 0x483877F: malloc (vg_replace_malloc.c:307)
==34772==    by 0x49809C7: ??? (in /usr/lib/x86_64-linux-gnu/libpython3.9.so.1.0)
==34772==    by 0x4A72244: _PyObject_GC_Malloc (in /usr/lib/x86_64-linux-gnu/libpython3.9.so.1.0)
==34772==    by 0x4A72567: _PyObject_GC_NewVar (in /usr/lib/x86_64-linux-gnu/libpython3.9.so.1.0)
==34772==    by 0x48E3750: ??? (in /usr/lib/x86_64-linux-gnu/libpython3.9.so.1.0)
==34772==    by 0x4A0E565: ??? (in /usr/lib/x86_64-linux-gnu/libpython3.9.so.1.0)
==34772==    by 0x492BC7C: _PyFunction_Vectorcall (in /usr/lib/x86_64-linux-gnu/libpython3.9.so.1.0)
==34772==    by 0x48E0115: _PyEval_EvalFrameDefault (in /usr/lib/x86_64-linux-gnu/libpython3.9.so.1.0)
==34772==    by 0x4A0EDDB: ??? (in /usr/lib/x86_64-linux-gnu/libpython3.9.so.1.0)
==34772==    by 0x492BC7C: _PyFunction_Vectorcall (in /usr/lib/x86_64-linux-gnu/libpython3.9.so.1.0)
==34772==    by 0x48E0115: _PyEval_EvalFrameDefault (in /usr/lib/x86_64-linux-gnu/libpython3.9.so.1.0)
==34772==    by 0x48D9032: ??? (in /usr/lib/x86_64-linux-gnu/libpython3.9.so.1.0)
==34772==
==34772== 528 bytes in 1 blocks are possibly lost in loss record 32,107 of 35,156
==34772==    at 0x483877F: malloc (vg_replace_malloc.c:307)
==34772==    by 0x49809C7: ??? (in /usr/lib/x86_64-linux-gnu/libpython3.9.so.1.0)
==34772==    by 0x4A72244: _PyObject_GC_Malloc (in /usr/lib/x86_64-linux-gnu/libpython3.9.so.1.0)
==34772==    by 0x4A72567: _PyObject_GC_NewVar (in /usr/lib/x86_64-linux-gnu/libpython3.9.so.1.0)
==34772==    by 0x48E3750: ??? (in /usr/lib/x86_64-linux-gnu/libpython3.9.so.1.0)
==34772==    by 0x4A0E565: ??? (in /usr/lib/x86_64-linux-gnu/libpython3.9.so.1.0)
==34772==    by 0x492BC7C: _PyFunction_Vectorcall (in /usr/lib/x86_64-linux-gnu/libpython3.9.so.1.0)
==34772==    by 0x49337BB: ??? (in /usr/lib/x86_64-linux-gnu/libpython3.9.so.1.0)
==34772==    by 0x4932F22: _PyObject_FastCallDictTstate (in /usr/lib/x86_64-linux-gnu/libpython3.9.so.1.0)
==34772==    by 0x4996C01: ??? (in /usr/lib/x86_64-linux-gnu/libpython3.9.so.1.0)
==34772==    by 0x4998DD3: ??? (in /usr/lib/x86_64-linux-gnu/libpython3.9.so.1.0)
==34772==    by 0x4976C92: ??? (in /usr/lib/x86_64-linux-gnu/libpython3.9.so.1.0)
==34772==
==34772== 528 bytes in 1 blocks are possibly lost in loss record 32,108 of 35,156
==34772==    at 0x483877F: malloc (vg_replace_malloc.c:307)
==34772==    by 0x49809C7: ??? (in /usr/lib/x86_64-linux-gnu/libpython3.9.so.1.0)
==34772==    by 0x4A72244: _PyObject_GC_Malloc (in /usr/lib/x86_64-linux-gnu/libpython3.9.so.1.0)
==34772==    by 0x4A72567: _PyObject_GC_NewVar (in /usr/lib/x86_64-linux-gnu/libpython3.9.so.1.0)
==34772==    by 0x48E3750: ??? (in /usr/lib/x86_64-linux-gnu/libpython3.9.so.1.0)
==34772==    by 0x48D8FF0: ??? (in /usr/lib/x86_64-linux-gnu/libpython3.9.so.1.0)
==34772==    by 0x4933727: ??? (in /usr/lib/x86_64-linux-gnu/libpython3.9.so.1.0)
==34772==    by 0x48E1584: _PyEval_EvalFrameDefault (in /usr/lib/x86_64-linux-gnu/libpython3.9.so.1.0)
==34772==    by 0x48D9032: ??? (in /usr/lib/x86_64-linux-gnu/libpython3.9.so.1.0)
==34772==    by 0x4933727: ??? (in /usr/lib/x86_64-linux-gnu/libpython3.9.so.1.0)
==34772==    by 0x48E1584: _PyEval_EvalFrameDefault (in /usr/lib/x86_64-linux-gnu/libpython3.9.so.1.0)
==34772==    by 0x4A0EDDB: ??? (in /usr/lib/x86_64-linux-gnu/libpython3.9.so.1.0)
==34772==
==34772== 528 bytes in 1 blocks are possibly lost in loss record 32,109 of 35,156
==34772==    at 0x483877F: malloc (vg_replace_malloc.c:307)
==34772==    by 0x49809C7: ??? (in /usr/lib/x86_64-linux-gnu/libpython3.9.so.1.0)
==34772==    by 0x4A72244: _PyObject_GC_Malloc (in /usr/lib/x86_64-linux-gnu/libpython3.9.so.1.0)
==34772==    by 0x4A72567: _PyObject_GC_NewVar (in /usr/lib/x86_64-linux-gnu/libpython3.9.so.1.0)
==34772==    by 0x48E3750: ??? (in /usr/lib/x86_64-linux-gnu/libpython3.9.so.1.0)
==34772==    by 0x48D8FF0: ??? (in /usr/lib/x86_64-linux-gnu/libpython3.9.so.1.0)
==34772==    by 0x498E52E: ??? (in /usr/lib/x86_64-linux-gnu/libpython3.9.so.1.0)
==34772==    by 0x49905C5: ??? (in /usr/lib/x86_64-linux-gnu/libpython3.9.so.1.0)
==34772==    by 0x497AAFE: PyObject_SetAttr (in /usr/lib/x86_64-linux-gnu/libpython3.9.so.1.0)
==34772==    by 0x48DA9DA: _PyEval_EvalFrameDefault (in /usr/lib/x86_64-linux-gnu/libpython3.9.so.1.0)
==34772==    by 0x4A0EDDB: ??? (in /usr/lib/x86_64-linux-gnu/libpython3.9.so.1.0)
==34772==    by 0x492BC7C: _PyFunction_Vectorcall (in /usr/lib/x86_64-linux-gnu/libpython3.9.so.1.0)
==34772==
==34772== 528 bytes in 1 blocks are possibly lost in loss record 32,110 of 35,156
==34772==    at 0x483877F: malloc (vg_replace_malloc.c:307)
==34772==    by 0x49809C7: ??? (in /usr/lib/x86_64-linux-gnu/libpython3.9.so.1.0)
==34772==    by 0x4A72244: _PyObject_GC_Malloc (in /usr/lib/x86_64-linux-gnu/libpython3.9.so.1.0)
==34772==    by 0x4A72567: _PyObject_GC_NewVar (in /usr/lib/x86_64-linux-gnu/libpython3.9.so.1.0)
==34772==    by 0x48E3750: ??? (in /usr/lib/x86_64-linux-gnu/libpython3.9.so.1.0)
==34772==    by 0x48D8FF0: ??? (in /usr/lib/x86_64-linux-gnu/libpython3.9.so.1.0)
==34772==    by 0x48E0115: _PyEval_EvalFrameDefault (in /usr/lib/x86_64-linux-gnu/libpython3.9.so.1.0)
==34772==    by 0x4A0EDDB: ??? (in /usr/lib/x86_64-linux-gnu/libpython3.9.so.1.0)
==34772==    by 0x492BC7C: _PyFunction_Vectorcall (in /usr/lib/x86_64-linux-gnu/libpython3.9.so.1.0)
==34772==    by 0x48DFC4C: _PyEval_EvalFrameDefault (in /usr/lib/x86_64-linux-gnu/libpython3.9.so.1.0)
==34772==    by 0x4A0EDDB: ??? (in /usr/lib/x86_64-linux-gnu/libpython3.9.so.1.0)
==34772==    by 0x492BC7C: _PyFunction_Vectorcall (in /usr/lib/x86_64-linux-gnu/libpython3.9.so.1.0)
==34772==
==34772== 528 bytes in 1 blocks are possibly lost in loss record 32,111 of 35,156
==34772==    at 0x483877F: malloc (vg_replace_malloc.c:307)
==34772==    by 0x49809C7: ??? (in /usr/lib/x86_64-linux-gnu/libpython3.9.so.1.0)
==34772==    by 0x4980ABF: ??? (in /usr/lib/x86_64-linux-gnu/libpython3.9.so.1.0)
==34772==    by 0x4A6E0D4: _PyObject_GC_Resize (in /usr/lib/x86_64-linux-gnu/libpython3.9.so.1.0)
==34772==    by 0x48E3568: ??? (in /usr/lib/x86_64-linux-gnu/libpython3.9.so.1.0)
==34772==    by 0x4A0E565: ??? (in /usr/lib/x86_64-linux-gnu/libpython3.9.so.1.0)
==34772==    by 0x492BC7C: _PyFunction_Vectorcall (in /usr/lib/x86_64-linux-gnu/libpython3.9.so.1.0)
==34772==    by 0x48E0115: _PyEval_EvalFrameDefault (in /usr/lib/x86_64-linux-gnu/libpython3.9.so.1.0)
==34772==    by 0x48D9032: ??? (in /usr/lib/x86_64-linux-gnu/libpython3.9.so.1.0)
==34772==    by 0x48E1584: _PyEval_EvalFrameDefault (in /usr/lib/x86_64-linux-gnu/libpython3.9.so.1.0)
==34772==    by 0x48D9032: ??? (in /usr/lib/x86_64-linux-gnu/libpython3.9.so.1.0)
==34772==    by 0x3369BE: pybind11::detail::simple_collector<(pybind11::return_value_policy)1>::call(_object*) const (cast.h:1465)
==34772==
==34772== 528 bytes in 1 blocks are possibly lost in loss record 32,112 of 35,156
==34772==    at 0x483877F: malloc (vg_replace_malloc.c:307)
==34772==    by 0x49809C7: ??? (in /usr/lib/x86_64-linux-gnu/libpython3.9.so.1.0)
==34772==    by 0x4980ABF: ??? (in /usr/lib/x86_64-linux-gnu/libpython3.9.so.1.0)
==34772==    by 0x4A6E0D4: _PyObject_GC_Resize (in /usr/lib/x86_64-linux-gnu/libpython3.9.so.1.0)
==34772==    by 0x48E3568: ??? (in /usr/lib/x86_64-linux-gnu/libpython3.9.so.1.0)
==34772==    by 0x4A0E565: ??? (in /usr/lib/x86_64-linux-gnu/libpython3.9.so.1.0)
==34772==    by 0x492BC7C: _PyFunction_Vectorcall (in /usr/lib/x86_64-linux-gnu/libpython3.9.so.1.0)
==34772==    by 0x48E14B6: _PyEval_EvalFrameDefault (in /usr/lib/x86_64-linux-gnu/libpython3.9.so.1.0)
==34772==    by 0x4A0EDDB: ??? (in /usr/lib/x86_64-linux-gnu/libpython3.9.so.1.0)
==34772==    by 0x492BC7C: _PyFunction_Vectorcall (in /usr/lib/x86_64-linux-gnu/libpython3.9.so.1.0)
==34772==    by 0x4932F22: _PyObject_FastCallDictTstate (in /usr/lib/x86_64-linux-gnu/libpython3.9.so.1.0)
==34772==    by 0x493313F: _PyObject_Call_Prepend (in /usr/lib/x86_64-linux-gnu/libpython3.9.so.1.0)
==34772==
==34772== 528 bytes in 1 blocks are possibly lost in loss record 32,113 of 35,156
==34772==    at 0x483877F: malloc (vg_replace_malloc.c:307)
==34772==    by 0x49809C7: ??? (in /usr/lib/x86_64-linux-gnu/libpython3.9.so.1.0)
==34772==    by 0x4980ABF: ??? (in /usr/lib/x86_64-linux-gnu/libpython3.9.so.1.0)
==34772==    by 0x4A6E0D4: _PyObject_GC_Resize (in /usr/lib/x86_64-linux-gnu/libpython3.9.so.1.0)
==34772==    by 0x48E3568: ??? (in /usr/lib/x86_64-linux-gnu/libpython3.9.so.1.0)
==34772==    by 0x4A0E565: ??? (in /usr/lib/x86_64-linux-gnu/libpython3.9.so.1.0)
==34772==    by 0x492BC7C: _PyFunction_Vectorcall (in /usr/lib/x86_64-linux-gnu/libpython3.9.so.1.0)
==34772==    by 0x48E14B6: _PyEval_EvalFrameDefault (in /usr/lib/x86_64-linux-gnu/libpython3.9.so.1.0)
==34772==    by 0x4A0EDDB: ??? (in /usr/lib/x86_64-linux-gnu/libpython3.9.so.1.0)
==34772==    by 0x492BC7C: _PyFunction_Vectorcall (in /usr/lib/x86_64-linux-gnu/libpython3.9.so.1.0)
==34772==    by 0x48DFC4C: _PyEval_EvalFrameDefault (in /usr/lib/x86_64-linux-gnu/libpython3.9.so.1.0)
==34772==    by 0x4A0EDDB: ??? (in /usr/lib/x86_64-linux-gnu/libpython3.9.so.1.0)
==34772==
==34772== 536 bytes in 1 blocks are possibly lost in loss record 32,118 of 35,156
==34772==    at 0x483877F: malloc (vg_replace_malloc.c:307)
==34772==    by 0x49809C7: ??? (in /usr/lib/x86_64-linux-gnu/libpython3.9.so.1.0)
==34772==    by 0x4A72244: _PyObject_GC_Malloc (in /usr/lib/x86_64-linux-gnu/libpython3.9.so.1.0)
==34772==    by 0x4A72567: _PyObject_GC_NewVar (in /usr/lib/x86_64-linux-gnu/libpython3.9.so.1.0)
==34772==    by 0x498A405: ??? (in /usr/lib/x86_64-linux-gnu/libpython3.9.so.1.0)
==34772==    by 0x4A47D56: ??? (in /usr/lib/x86_64-linux-gnu/libpython3.9.so.1.0)
==34772==    by 0x4B56E3F: ??? (in /usr/lib/x86_64-linux-gnu/libpython3.9.so.1.0)
==34772==    by 0x4A4B700: Py_InitializeFromConfig (in /usr/lib/x86_64-linux-gnu/libpython3.9.so.1.0)
==34772==    by 0xEB35AE: pybind11::initialize_interpreter(PyConfig*, int, char const* const*, bool) (embed.h:157)
==34772==    by 0xEB3732: pybind11::initialize_interpreter(bool, int, char const* const*, bool) (embed.h:205)
==34772==    by 0xEB398A: pybind11::scoped_interpreter::scoped_interpreter(bool, int, char const* const*, bool) (embed.h:290)
==34772==    by 0xEB2A7A: main (main.cc:63)
==34772==
==34772== 536 bytes in 1 blocks are possibly lost in loss record 32,119 of 35,156
==34772==    at 0x483877F: malloc (vg_replace_malloc.c:307)
==34772==    by 0x49809C7: ??? (in /usr/lib/x86_64-linux-gnu/libpython3.9.so.1.0)
==34772==    by 0x4A72244: _PyObject_GC_Malloc (in /usr/lib/x86_64-linux-gnu/libpython3.9.so.1.0)
==34772==    by 0x4A72567: _PyObject_GC_NewVar (in /usr/lib/x86_64-linux-gnu/libpython3.9.so.1.0)
==34772==    by 0x48E3750: ??? (in /usr/lib/x86_64-linux-gnu/libpython3.9.so.1.0)
==34772==    by 0x48D8FF0: ??? (in /usr/lib/x86_64-linux-gnu/libpython3.9.so.1.0)
==34772==    by 0x48E0115: _PyEval_EvalFrameDefault (in /usr/lib/x86_64-linux-gnu/libpython3.9.so.1.0)
==34772==    by 0x48D9032: ??? (in /usr/lib/x86_64-linux-gnu/libpython3.9.so.1.0)
==34772==    by 0x48E1584: _PyEval_EvalFrameDefault (in /usr/lib/x86_64-linux-gnu/libpython3.9.so.1.0)
==34772==    by 0x48D9032: ??? (in /usr/lib/x86_64-linux-gnu/libpython3.9.so.1.0)
==34772==    by 0x49341F5: PyObject_CallMethod (in /usr/lib/x86_64-linux-gnu/libpython3.9.so.1.0)
==34772==    by 0x4A4A22C: ??? (in /usr/lib/x86_64-linux-gnu/libpython3.9.so.1.0)
==34772==
==34772== 536 bytes in 1 blocks are possibly lost in loss record 32,120 of 35,156
==34772==    at 0x483877F: malloc (vg_replace_malloc.c:307)
==34772==    by 0x49809C7: ??? (in /usr/lib/x86_64-linux-gnu/libpython3.9.so.1.0)
==34772==    by 0x4A72244: _PyObject_GC_Malloc (in /usr/lib/x86_64-linux-gnu/libpython3.9.so.1.0)
==34772==    by 0x4A72567: _PyObject_GC_NewVar (in /usr/lib/x86_64-linux-gnu/libpython3.9.so.1.0)
==34772==    by 0x48E3750: ??? (in /usr/lib/x86_64-linux-gnu/libpython3.9.so.1.0)
==34772==    by 0x48D8FF0: ??? (in /usr/lib/x86_64-linux-gnu/libpython3.9.so.1.0)
==34772==    by 0x48E14B6: _PyEval_EvalFrameDefault (in /usr/lib/x86_64-linux-gnu/libpython3.9.so.1.0)
==34772==    by 0x4A0EDDB: ??? (in /usr/lib/x86_64-linux-gnu/libpython3.9.so.1.0)
==34772==    by 0x492BC7C: _PyFunction_Vectorcall (in /usr/lib/x86_64-linux-gnu/libpython3.9.so.1.0)
==34772==    by 0x48E14B6: _PyEval_EvalFrameDefault (in /usr/lib/x86_64-linux-gnu/libpython3.9.so.1.0)
==34772==    by 0x4A0EDDB: ??? (in /usr/lib/x86_64-linux-gnu/libpython3.9.so.1.0)
==34772==    by 0x492BC7C: _PyFunction_Vectorcall (in /usr/lib/x86_64-linux-gnu/libpython3.9.so.1.0)
==34772==
==34772== 536 bytes in 1 blocks are possibly lost in loss record 32,121 of 35,156
==34772==    at 0x483AD7B: realloc (vg_replace_malloc.c:834)
==34772==    by 0x4A6E0D4: _PyObject_GC_Resize (in /usr/lib/x86_64-linux-gnu/libpython3.9.so.1.0)
==34772==    by 0x48E3568: ??? (in /usr/lib/x86_64-linux-gnu/libpython3.9.so.1.0)
==34772==    by 0x4A0E565: ??? (in /usr/lib/x86_64-linux-gnu/libpython3.9.so.1.0)
==34772==    by 0x492BC7C: _PyFunction_Vectorcall (in /usr/lib/x86_64-linux-gnu/libpython3.9.so.1.0)
==34772==    by 0x4932723: ??? (in /usr/lib/x86_64-linux-gnu/libpython3.9.so.1.0)
==34772==    by 0x4932A8A: _PyObject_CallMethodIdObjArgs (in /usr/lib/x86_64-linux-gnu/libpython3.9.so.1.0)
==34772==    by 0x4A34BDC: PyImport_ImportModuleLevelObject (in /usr/lib/x86_64-linux-gnu/libpython3.9.so.1.0)
==34772==    by 0x48E0AD1: _PyEval_EvalFrameDefault (in /usr/lib/x86_64-linux-gnu/libpython3.9.so.1.0)
==34772==    by 0x4A0EDDB: ??? (in /usr/lib/x86_64-linux-gnu/libpython3.9.so.1.0)
==34772==    by 0x4A0F12D: _PyEval_EvalCodeWithName (in /usr/lib/x86_64-linux-gnu/libpython3.9.so.1.0)
==34772==    by 0x4A0F17D: PyEval_EvalCodeEx (in /usr/lib/x86_64-linux-gnu/libpython3.9.so.1.0)
==34772==
==34772== 536 bytes in 1 blocks are possibly lost in loss record 32,122 of 35,156
==34772==    at 0x483877F: malloc (vg_replace_malloc.c:307)
==34772==    by 0x49809C7: ??? (in /usr/lib/x86_64-linux-gnu/libpython3.9.so.1.0)
==34772==    by 0x4980ABF: ??? (in /usr/lib/x86_64-linux-gnu/libpython3.9.so.1.0)
==34772==    by 0x4A6E0D4: _PyObject_GC_Resize (in /usr/lib/x86_64-linux-gnu/libpython3.9.so.1.0)
==34772==    by 0x48E3568: ??? (in /usr/lib/x86_64-linux-gnu/libpython3.9.so.1.0)
==34772==    by 0x48D8FF0: ??? (in /usr/lib/x86_64-linux-gnu/libpython3.9.so.1.0)
==34772==    by 0x4A12A34: _PyCodec_Lookup (in /usr/lib/x86_64-linux-gnu/libpython3.9.so.1.0)
==34772==    by 0x49D9E54: ??? (in /usr/lib/x86_64-linux-gnu/libpython3.9.so.1.0)
==34772==    by 0x4A4A2FC: ??? (in /usr/lib/x86_64-linux-gnu/libpython3.9.so.1.0)
==34772==    by 0x4A4B7A7: Py_InitializeFromConfig (in /usr/lib/x86_64-linux-gnu/libpython3.9.so.1.0)
==34772==    by 0xEB35AE: pybind11::initialize_interpreter(PyConfig*, int, char const* const*, bool) (embed.h:157)
==34772==    by 0xEB3732: pybind11::initialize_interpreter(bool, int, char const* const*, bool) (embed.h:205)
==34772==
==34772== 536 bytes in 1 blocks are possibly lost in loss record 32,123 of 35,156
==34772==    at 0x483877F: malloc (vg_replace_malloc.c:307)
==34772==    by 0x49809C7: ??? (in /usr/lib/x86_64-linux-gnu/libpython3.9.so.1.0)
==34772==    by 0x4A72244: _PyObject_GC_Malloc (in /usr/lib/x86_64-linux-gnu/libpython3.9.so.1.0)
==34772==    by 0x4A72567: _PyObject_GC_NewVar (in /usr/lib/x86_64-linux-gnu/libpython3.9.so.1.0)
==34772==    by 0x48E3750: ??? (in /usr/lib/x86_64-linux-gnu/libpython3.9.so.1.0)
==34772==    by 0x4A0E565: ??? (in /usr/lib/x86_64-linux-gnu/libpython3.9.so.1.0)
==34772==    by 0x4A0F12D: _PyEval_EvalCodeWithName (in /usr/lib/x86_64-linux-gnu/libpython3.9.so.1.0)
==34772==    by 0x4A0F17D: PyEval_EvalCodeEx (in /usr/lib/x86_64-linux-gnu/libpython3.9.so.1.0)
==34772==    by 0x4A0A72A: PyEval_EvalCode (in /usr/lib/x86_64-linux-gnu/libpython3.9.so.1.0)
==34772==    by 0x4A092A0: ??? (in /usr/lib/x86_64-linux-gnu/libpython3.9.so.1.0)
==34772==    by 0x497BE83: ??? (in /usr/lib/x86_64-linux-gnu/libpython3.9.so.1.0)
==34772==    by 0x48E0115: _PyEval_EvalFrameDefault (in /usr/lib/x86_64-linux-gnu/libpython3.9.so.1.0)
==34772==
==34772== 536 bytes in 1 blocks are possibly lost in loss record 32,124 of 35,156
==34772==    at 0x483AD7B: realloc (vg_replace_malloc.c:834)
==34772==    by 0x4A6E0D4: _PyObject_GC_Resize (in /usr/lib/x86_64-linux-gnu/libpython3.9.so.1.0)
==34772==    by 0x48E3568: ??? (in /usr/lib/x86_64-linux-gnu/libpython3.9.so.1.0)
==34772==    by 0x4A0E565: ??? (in /usr/lib/x86_64-linux-gnu/libpython3.9.so.1.0)
==34772==    by 0x492BC7C: _PyFunction_Vectorcall (in /usr/lib/x86_64-linux-gnu/libpython3.9.so.1.0)
==34772==    by 0x48E1584: _PyEval_EvalFrameDefault (in /usr/lib/x86_64-linux-gnu/libpython3.9.so.1.0)
==34772==    by 0x4A0EDDB: ??? (in /usr/lib/x86_64-linux-gnu/libpython3.9.so.1.0)
==34772==    by 0x492BC7C: _PyFunction_Vectorcall (in /usr/lib/x86_64-linux-gnu/libpython3.9.so.1.0)
==34772==    by 0x48E1584: _PyEval_EvalFrameDefault (in /usr/lib/x86_64-linux-gnu/libpython3.9.so.1.0)
==34772==    by 0x4A0EDDB: ??? (in /usr/lib/x86_64-linux-gnu/libpython3.9.so.1.0)
==34772==    by 0x4A0F12D: _PyEval_EvalCodeWithName (in /usr/lib/x86_64-linux-gnu/libpython3.9.so.1.0)
==34772==    by 0x4A0F17D: PyEval_EvalCodeEx (in /usr/lib/x86_64-linux-gnu/libpython3.9.so.1.0)
==34772==
==34772== 544 bytes in 1 blocks are possibly lost in loss record 32,130 of 35,156
==34772==    at 0x483877F: malloc (vg_replace_malloc.c:307)
==34772==    by 0x49809C7: ??? (in /usr/lib/x86_64-linux-gnu/libpython3.9.so.1.0)
==34772==    by 0x4A72244: _PyObject_GC_Malloc (in /usr/lib/x86_64-linux-gnu/libpython3.9.so.1.0)
==34772==    by 0x4A72567: _PyObject_GC_NewVar (in /usr/lib/x86_64-linux-gnu/libpython3.9.so.1.0)
==34772==    by 0x48E3750: ??? (in /usr/lib/x86_64-linux-gnu/libpython3.9.so.1.0)
==34772==    by 0x4A0E565: ??? (in /usr/lib/x86_64-linux-gnu/libpython3.9.so.1.0)
==34772==    by 0x492BC7C: _PyFunction_Vectorcall (in /usr/lib/x86_64-linux-gnu/libpython3.9.so.1.0)
==34772==    by 0x48E0115: _PyEval_EvalFrameDefault (in /usr/lib/x86_64-linux-gnu/libpython3.9.so.1.0)
==34772==    by 0x48D9032: ??? (in /usr/lib/x86_64-linux-gnu/libpython3.9.so.1.0)
==34772==    by 0x48E0115: _PyEval_EvalFrameDefault (in /usr/lib/x86_64-linux-gnu/libpython3.9.so.1.0)
==34772==    by 0x48D9032: ??? (in /usr/lib/x86_64-linux-gnu/libpython3.9.so.1.0)
==34772==    by 0x4932723: ??? (in /usr/lib/x86_64-linux-gnu/libpython3.9.so.1.0)
==34772==
==34772== 544 bytes in 1 blocks are possibly lost in loss record 32,131 of 35,156
==34772==    at 0x483877F: malloc (vg_replace_malloc.c:307)
==34772==    by 0x49809C7: ??? (in /usr/lib/x86_64-linux-gnu/libpython3.9.so.1.0)
==34772==    by 0x4A72244: _PyObject_GC_Malloc (in /usr/lib/x86_64-linux-gnu/libpython3.9.so.1.0)
==34772==    by 0x4A72567: _PyObject_GC_NewVar (in /usr/lib/x86_64-linux-gnu/libpython3.9.so.1.0)
==34772==    by 0x48E3750: ??? (in /usr/lib/x86_64-linux-gnu/libpython3.9.so.1.0)
==34772==    by 0x4A0E565: ??? (in /usr/lib/x86_64-linux-gnu/libpython3.9.so.1.0)
==34772==    by 0x492BC7C: _PyFunction_Vectorcall (in /usr/lib/x86_64-linux-gnu/libpython3.9.so.1.0)
==34772==    by 0x48E1584: _PyEval_EvalFrameDefault (in /usr/lib/x86_64-linux-gnu/libpython3.9.so.1.0)
==34772==    by 0x4A0EDDB: ??? (in /usr/lib/x86_64-linux-gnu/libpython3.9.so.1.0)
==34772==    by 0x4A0F12D: _PyEval_EvalCodeWithName (in /usr/lib/x86_64-linux-gnu/libpython3.9.so.1.0)
==34772==    by 0x4A0F17D: PyEval_EvalCodeEx (in /usr/lib/x86_64-linux-gnu/libpython3.9.so.1.0)
==34772==    by 0x4A0A72A: PyEval_EvalCode (in /usr/lib/x86_64-linux-gnu/libpython3.9.so.1.0)
==34772==
==34772== 544 bytes in 1 blocks are possibly lost in loss record 32,132 of 35,156
==34772==    at 0x483877F: malloc (vg_replace_malloc.c:307)
==34772==    by 0x49809C7: ??? (in /usr/lib/x86_64-linux-gnu/libpython3.9.so.1.0)
==34772==    by 0x4A72244: _PyObject_GC_Malloc (in /usr/lib/x86_64-linux-gnu/libpython3.9.so.1.0)
==34772==    by 0x4A72567: _PyObject_GC_NewVar (in /usr/lib/x86_64-linux-gnu/libpython3.9.so.1.0)
==34772==    by 0x48E3750: ??? (in /usr/lib/x86_64-linux-gnu/libpython3.9.so.1.0)
==34772==    by 0x48D8FF0: ??? (in /usr/lib/x86_64-linux-gnu/libpython3.9.so.1.0)
==34772==    by 0x48E0115: _PyEval_EvalFrameDefault (in /usr/lib/x86_64-linux-gnu/libpython3.9.so.1.0)
==34772==    by 0x4A0EDDB: ??? (in /usr/lib/x86_64-linux-gnu/libpython3.9.so.1.0)
==34772==    by 0x4A0F12D: _PyEval_EvalCodeWithName (in /usr/lib/x86_64-linux-gnu/libpython3.9.so.1.0)
==34772==    by 0x4A0F17D: PyEval_EvalCodeEx (in /usr/lib/x86_64-linux-gnu/libpython3.9.so.1.0)
==34772==    by 0x4A0A72A: PyEval_EvalCode (in /usr/lib/x86_64-linux-gnu/libpython3.9.so.1.0)
==34772==    by 0x4A092A0: ??? (in /usr/lib/x86_64-linux-gnu/libpython3.9.so.1.0)
==34772==
==34772== 544 bytes in 1 blocks are possibly lost in loss record 32,133 of 35,156
==34772==    at 0x483AD7B: realloc (vg_replace_malloc.c:834)
==34772==    by 0x4A6E0D4: _PyObject_GC_Resize (in /usr/lib/x86_64-linux-gnu/libpython3.9.so.1.0)
==34772==    by 0x48E3568: ??? (in /usr/lib/x86_64-linux-gnu/libpython3.9.so.1.0)
==34772==    by 0x48D8FF0: ??? (in /usr/lib/x86_64-linux-gnu/libpython3.9.so.1.0)
==34772==    by 0x48E1584: _PyEval_EvalFrameDefault (in /usr/lib/x86_64-linux-gnu/libpython3.9.so.1.0)
==34772==    by 0x48D9032: ??? (in /usr/lib/x86_64-linux-gnu/libpython3.9.so.1.0)
==34772==    by 0x48E0115: _PyEval_EvalFrameDefault (in /usr/lib/x86_64-linux-gnu/libpython3.9.so.1.0)
==34772==    by 0x4A0EDDB: ??? (in /usr/lib/x86_64-linux-gnu/libpython3.9.so.1.0)
==34772==    by 0x492BC7C: _PyFunction_Vectorcall (in /usr/lib/x86_64-linux-gnu/libpython3.9.so.1.0)
==34772==    by 0x48E1584: _PyEval_EvalFrameDefault (in /usr/lib/x86_64-linux-gnu/libpython3.9.so.1.0)
==34772==    by 0x4A0EDDB: ??? (in /usr/lib/x86_64-linux-gnu/libpython3.9.so.1.0)
==34772==    by 0x4A0F12D: _PyEval_EvalCodeWithName (in /usr/lib/x86_64-linux-gnu/libpython3.9.so.1.0)
==34772==
==34772== 544 bytes in 1 blocks are possibly lost in loss record 32,134 of 35,156
==34772==    at 0x483877F: malloc (vg_replace_malloc.c:307)
==34772==    by 0x49809C7: ??? (in /usr/lib/x86_64-linux-gnu/libpython3.9.so.1.0)
==34772==    by 0x4980ABF: ??? (in /usr/lib/x86_64-linux-gnu/libpython3.9.so.1.0)
==34772==    by 0x4A6E0D4: _PyObject_GC_Resize (in /usr/lib/x86_64-linux-gnu/libpython3.9.so.1.0)
==34772==    by 0x48E3568: ??? (in /usr/lib/x86_64-linux-gnu/libpython3.9.so.1.0)
==34772==    by 0x48D8FF0: ??? (in /usr/lib/x86_64-linux-gnu/libpython3.9.so.1.0)
==34772==    by 0x4933727: ??? (in /usr/lib/x86_64-linux-gnu/libpython3.9.so.1.0)
==34772==    by 0x48E1584: _PyEval_EvalFrameDefault (in /usr/lib/x86_64-linux-gnu/libpython3.9.so.1.0)
==34772==    by 0x48D9032: ??? (in /usr/lib/x86_64-linux-gnu/libpython3.9.so.1.0)
==34772==    by 0x48E14B6: _PyEval_EvalFrameDefault (in /usr/lib/x86_64-linux-gnu/libpython3.9.so.1.0)
==34772==    by 0x48D9032: ??? (in /usr/lib/x86_64-linux-gnu/libpython3.9.so.1.0)
==34772==    by 0x48E14B6: _PyEval_EvalFrameDefault (in /usr/lib/x86_64-linux-gnu/libpython3.9.so.1.0)
==34772==
==34772== 552 bytes in 1 blocks are possibly lost in loss record 32,138 of 35,156
==34772==    at 0x483877F: malloc (vg_replace_malloc.c:307)
==34772==    by 0x49809C7: ??? (in /usr/lib/x86_64-linux-gnu/libpython3.9.so.1.0)
==34772==    by 0x4A72244: _PyObject_GC_Malloc (in /usr/lib/x86_64-linux-gnu/libpython3.9.so.1.0)
==34772==    by 0x4A72567: _PyObject_GC_NewVar (in /usr/lib/x86_64-linux-gnu/libpython3.9.so.1.0)
==34772==    by 0x48E3750: ??? (in /usr/lib/x86_64-linux-gnu/libpython3.9.so.1.0)
==34772==    by 0x48D8FF0: ??? (in /usr/lib/x86_64-linux-gnu/libpython3.9.so.1.0)
==34772==    by 0x48E0115: _PyEval_EvalFrameDefault (in /usr/lib/x86_64-linux-gnu/libpython3.9.so.1.0)
==34772==    by 0x48D9032: ??? (in /usr/lib/x86_64-linux-gnu/libpython3.9.so.1.0)
==34772==    by 0x48E0115: _PyEval_EvalFrameDefault (in /usr/lib/x86_64-linux-gnu/libpython3.9.so.1.0)
==34772==    by 0x48D9032: ??? (in /usr/lib/x86_64-linux-gnu/libpython3.9.so.1.0)
==34772==    by 0x48E0115: _PyEval_EvalFrameDefault (in /usr/lib/x86_64-linux-gnu/libpython3.9.so.1.0)
==34772==    by 0x48D9032: ??? (in /usr/lib/x86_64-linux-gnu/libpython3.9.so.1.0)
==34772==
==34772== 552 bytes in 1 blocks are possibly lost in loss record 32,139 of 35,156
==34772==    at 0x483AD7B: realloc (vg_replace_malloc.c:834)
==34772==    by 0x4A6E0D4: _PyObject_GC_Resize (in /usr/lib/x86_64-linux-gnu/libpython3.9.so.1.0)
==34772==    by 0x48E3568: ??? (in /usr/lib/x86_64-linux-gnu/libpython3.9.so.1.0)
==34772==    by 0x48D8FF0: ??? (in /usr/lib/x86_64-linux-gnu/libpython3.9.so.1.0)
==34772==    by 0x48E0115: _PyEval_EvalFrameDefault (in /usr/lib/x86_64-linux-gnu/libpython3.9.so.1.0)
==34772==    by 0x4A0EDDB: ??? (in /usr/lib/x86_64-linux-gnu/libpython3.9.so.1.0)
==34772==    by 0x492BC7C: _PyFunction_Vectorcall (in /usr/lib/x86_64-linux-gnu/libpython3.9.so.1.0)
==34772==    by 0x48E0115: _PyEval_EvalFrameDefault (in /usr/lib/x86_64-linux-gnu/libpython3.9.so.1.0)
==34772==    by 0x48D9032: ??? (in /usr/lib/x86_64-linux-gnu/libpython3.9.so.1.0)
==34772==    by 0x48E0115: _PyEval_EvalFrameDefault (in /usr/lib/x86_64-linux-gnu/libpython3.9.so.1.0)
==34772==    by 0x4A0EDDB: ??? (in /usr/lib/x86_64-linux-gnu/libpython3.9.so.1.0)
==34772==    by 0x492BC7C: _PyFunction_Vectorcall (in /usr/lib/x86_64-linux-gnu/libpython3.9.so.1.0)
==34772==
==34772== 552 bytes in 1 blocks are possibly lost in loss record 32,140 of 35,156
==34772==    at 0x483AD7B: realloc (vg_replace_malloc.c:834)
==34772==    by 0x4A6E0D4: _PyObject_GC_Resize (in /usr/lib/x86_64-linux-gnu/libpython3.9.so.1.0)
==34772==    by 0x48E3568: ??? (in /usr/lib/x86_64-linux-gnu/libpython3.9.so.1.0)
==34772==    by 0x48D8FF0: ??? (in /usr/lib/x86_64-linux-gnu/libpython3.9.so.1.0)
==34772==    by 0x48E0115: _PyEval_EvalFrameDefault (in /usr/lib/x86_64-linux-gnu/libpython3.9.so.1.0)
==34772==    by 0x48D9032: ??? (in /usr/lib/x86_64-linux-gnu/libpython3.9.so.1.0)
==34772==    by 0x48E0115: _PyEval_EvalFrameDefault (in /usr/lib/x86_64-linux-gnu/libpython3.9.so.1.0)
==34772==    by 0x4A0EDDB: ??? (in /usr/lib/x86_64-linux-gnu/libpython3.9.so.1.0)
==34772==    by 0x492BC7C: _PyFunction_Vectorcall (in /usr/lib/x86_64-linux-gnu/libpython3.9.so.1.0)
==34772==    by 0x48E0115: _PyEval_EvalFrameDefault (in /usr/lib/x86_64-linux-gnu/libpython3.9.so.1.0)
==34772==    by 0x48D9032: ??? (in /usr/lib/x86_64-linux-gnu/libpython3.9.so.1.0)
==34772==    by 0x48E0115: _PyEval_EvalFrameDefault (in /usr/lib/x86_64-linux-gnu/libpython3.9.so.1.0)
==34772==
==34772== 560 bytes in 1 blocks are possibly lost in loss record 32,143 of 35,156
==34772==    at 0x483877F: malloc (vg_replace_malloc.c:307)
==34772==    by 0x49809C7: ??? (in /usr/lib/x86_64-linux-gnu/libpython3.9.so.1.0)
==34772==    by 0x4A72244: _PyObject_GC_Malloc (in /usr/lib/x86_64-linux-gnu/libpython3.9.so.1.0)
==34772==    by 0x4A72567: _PyObject_GC_NewVar (in /usr/lib/x86_64-linux-gnu/libpython3.9.so.1.0)
==34772==    by 0x48E3750: ??? (in /usr/lib/x86_64-linux-gnu/libpython3.9.so.1.0)
==34772==    by 0x4A0E565: ??? (in /usr/lib/x86_64-linux-gnu/libpython3.9.so.1.0)
==34772==    by 0x492BC7C: _PyFunction_Vectorcall (in /usr/lib/x86_64-linux-gnu/libpython3.9.so.1.0)
==34772==    by 0x48E14B6: _PyEval_EvalFrameDefault (in /usr/lib/x86_64-linux-gnu/libpython3.9.so.1.0)
==34772==    by 0x4A0EDDB: ??? (in /usr/lib/x86_64-linux-gnu/libpython3.9.so.1.0)
==34772==    by 0x492BC7C: _PyFunction_Vectorcall (in /usr/lib/x86_64-linux-gnu/libpython3.9.so.1.0)
==34772==    by 0x4933727: ??? (in /usr/lib/x86_64-linux-gnu/libpython3.9.so.1.0)
==34772==    by 0x48E1584: _PyEval_EvalFrameDefault (in /usr/lib/x86_64-linux-gnu/libpython3.9.so.1.0)
==34772==
==34772== 560 bytes in 1 blocks are possibly lost in loss record 32,144 of 35,156
==34772==    at 0x483877F: malloc (vg_replace_malloc.c:307)
==34772==    by 0x49809C7: ??? (in /usr/lib/x86_64-linux-gnu/libpython3.9.so.1.0)
==34772==    by 0x4A72244: _PyObject_GC_Malloc (in /usr/lib/x86_64-linux-gnu/libpython3.9.so.1.0)
==34772==    by 0x4A72567: _PyObject_GC_NewVar (in /usr/lib/x86_64-linux-gnu/libpython3.9.so.1.0)
==34772==    by 0x48E3750: ??? (in /usr/lib/x86_64-linux-gnu/libpython3.9.so.1.0)
==34772==    by 0x48D8FF0: ??? (in /usr/lib/x86_64-linux-gnu/libpython3.9.so.1.0)
==34772==    by 0x48E0115: _PyEval_EvalFrameDefault (in /usr/lib/x86_64-linux-gnu/libpython3.9.so.1.0)
==34772==    by 0x48D9032: ??? (in /usr/lib/x86_64-linux-gnu/libpython3.9.so.1.0)
==34772==    by 0x48E0115: _PyEval_EvalFrameDefault (in /usr/lib/x86_64-linux-gnu/libpython3.9.so.1.0)
==34772==    by 0x4A0EDDB: ??? (in /usr/lib/x86_64-linux-gnu/libpython3.9.so.1.0)
==34772==    by 0x4A0F12D: _PyEval_EvalCodeWithName (in /usr/lib/x86_64-linux-gnu/libpython3.9.so.1.0)
==34772==    by 0x4A0F17D: PyEval_EvalCodeEx (in /usr/lib/x86_64-linux-gnu/libpython3.9.so.1.0)
==34772==
==34772== 560 bytes in 1 blocks are possibly lost in loss record 32,145 of 35,156
==34772==    at 0x483877F: malloc (vg_replace_malloc.c:307)
==34772==    by 0x49809C7: ??? (in /usr/lib/x86_64-linux-gnu/libpython3.9.so.1.0)
==34772==    by 0x4A72244: _PyObject_GC_Malloc (in /usr/lib/x86_64-linux-gnu/libpython3.9.so.1.0)
==34772==    by 0x4A72567: _PyObject_GC_NewVar (in /usr/lib/x86_64-linux-gnu/libpython3.9.so.1.0)
==34772==    by 0x48E3750: ??? (in /usr/lib/x86_64-linux-gnu/libpython3.9.so.1.0)
==34772==    by 0x4A0E565: ??? (in /usr/lib/x86_64-linux-gnu/libpython3.9.so.1.0)
==34772==    by 0x492BC7C: _PyFunction_Vectorcall (in /usr/lib/x86_64-linux-gnu/libpython3.9.so.1.0)
==34772==    by 0x48DE718: _PyEval_EvalFrameDefault (in /usr/lib/x86_64-linux-gnu/libpython3.9.so.1.0)
==34772==    by 0x4A0EDDB: ??? (in /usr/lib/x86_64-linux-gnu/libpython3.9.so.1.0)
==34772==    by 0x492BC7C: _PyFunction_Vectorcall (in /usr/lib/x86_64-linux-gnu/libpython3.9.so.1.0)
==34772==    by 0x48E0115: _PyEval_EvalFrameDefault (in /usr/lib/x86_64-linux-gnu/libpython3.9.so.1.0)
==34772==    by 0x4A0EDDB: ??? (in /usr/lib/x86_64-linux-gnu/libpython3.9.so.1.0)
==34772==
==34772== 568 bytes in 1 blocks are possibly lost in loss record 32,149 of 35,156
==34772==    at 0x483877F: malloc (vg_replace_malloc.c:307)
==34772==    by 0x49809C7: ??? (in /usr/lib/x86_64-linux-gnu/libpython3.9.so.1.0)
==34772==    by 0x4980ABF: ??? (in /usr/lib/x86_64-linux-gnu/libpython3.9.so.1.0)
==34772==    by 0x4A6E0D4: _PyObject_GC_Resize (in /usr/lib/x86_64-linux-gnu/libpython3.9.so.1.0)
==34772==    by 0x48E3568: ??? (in /usr/lib/x86_64-linux-gnu/libpython3.9.so.1.0)
==34772==    by 0x4A0E565: ??? (in /usr/lib/x86_64-linux-gnu/libpython3.9.so.1.0)
==34772==    by 0x492BC7C: _PyFunction_Vectorcall (in /usr/lib/x86_64-linux-gnu/libpython3.9.so.1.0)
==34772==    by 0x48E1584: _PyEval_EvalFrameDefault (in /usr/lib/x86_64-linux-gnu/libpython3.9.so.1.0)
==34772==    by 0x4A0EDDB: ??? (in /usr/lib/x86_64-linux-gnu/libpython3.9.so.1.0)
==34772==    by 0x492BC7C: _PyFunction_Vectorcall (in /usr/lib/x86_64-linux-gnu/libpython3.9.so.1.0)
==34772==    by 0x48E1584: _PyEval_EvalFrameDefault (in /usr/lib/x86_64-linux-gnu/libpython3.9.so.1.0)
==34772==    by 0x4A0EDDB: ??? (in /usr/lib/x86_64-linux-gnu/libpython3.9.so.1.0)
==34772==
==34772== 576 bytes in 1 blocks are possibly lost in loss record 32,251 of 35,156
==34772==    at 0x483877F: malloc (vg_replace_malloc.c:307)
==34772==    by 0x49809C7: ??? (in /usr/lib/x86_64-linux-gnu/libpython3.9.so.1.0)
==34772==    by 0x4A72244: _PyObject_GC_Malloc (in /usr/lib/x86_64-linux-gnu/libpython3.9.so.1.0)
==34772==    by 0x4A72567: _PyObject_GC_NewVar (in /usr/lib/x86_64-linux-gnu/libpython3.9.so.1.0)
==34772==    by 0x48E3750: ??? (in /usr/lib/x86_64-linux-gnu/libpython3.9.so.1.0)
==34772==    by 0x48D8FF0: ??? (in /usr/lib/x86_64-linux-gnu/libpython3.9.so.1.0)
==34772==    by 0x48E14B6: _PyEval_EvalFrameDefault (in /usr/lib/x86_64-linux-gnu/libpython3.9.so.1.0)
==34772==    by 0x48D9032: ??? (in /usr/lib/x86_64-linux-gnu/libpython3.9.so.1.0)
==34772==    by 0x48E14B6: _PyEval_EvalFrameDefault (in /usr/lib/x86_64-linux-gnu/libpython3.9.so.1.0)
==34772==    by 0x48D9032: ??? (in /usr/lib/x86_64-linux-gnu/libpython3.9.so.1.0)
==34772==    by 0x48E0115: _PyEval_EvalFrameDefault (in /usr/lib/x86_64-linux-gnu/libpython3.9.so.1.0)
==34772==    by 0x48D9032: ??? (in /usr/lib/x86_64-linux-gnu/libpython3.9.so.1.0)
==34772==
==34772== 576 bytes in 1 blocks are possibly lost in loss record 32,252 of 35,156
==34772==    at 0x483877F: malloc (vg_replace_malloc.c:307)
==34772==    by 0x49809C7: ??? (in /usr/lib/x86_64-linux-gnu/libpython3.9.so.1.0)
==34772==    by 0x4A72244: _PyObject_GC_Malloc (in /usr/lib/x86_64-linux-gnu/libpython3.9.so.1.0)
==34772==    by 0x4A72567: _PyObject_GC_NewVar (in /usr/lib/x86_64-linux-gnu/libpython3.9.so.1.0)
==34772==    by 0x48E3750: ??? (in /usr/lib/x86_64-linux-gnu/libpython3.9.so.1.0)
==34772==    by 0x4A0E565: ??? (in /usr/lib/x86_64-linux-gnu/libpython3.9.so.1.0)
==34772==    by 0x492BC7C: _PyFunction_Vectorcall (in /usr/lib/x86_64-linux-gnu/libpython3.9.so.1.0)
==34772==    by 0x48E1584: _PyEval_EvalFrameDefault (in /usr/lib/x86_64-linux-gnu/libpython3.9.so.1.0)
==34772==    by 0x48D9032: ??? (in /usr/lib/x86_64-linux-gnu/libpython3.9.so.1.0)
==34772==    by 0x4A98CA5: ??? (in /usr/lib/x86_64-linux-gnu/libpython3.9.so.1.0)
==34772==    by 0x4930A4F: _PyObject_MakeTpCall (in /usr/lib/x86_64-linux-gnu/libpython3.9.so.1.0)
==34772==    by 0x48E0F07: _PyEval_EvalFrameDefault (in /usr/lib/x86_64-linux-gnu/libpython3.9.so.1.0)
==34772==
==34772== 576 bytes in 1 blocks are possibly lost in loss record 32,253 of 35,156
==34772==    at 0x483AD7B: realloc (vg_replace_malloc.c:834)
==34772==    by 0x4A6E0D4: _PyObject_GC_Resize (in /usr/lib/x86_64-linux-gnu/libpython3.9.so.1.0)
==34772==    by 0x48E3568: ??? (in /usr/lib/x86_64-linux-gnu/libpython3.9.so.1.0)
==34772==    by 0x4A0E565: ??? (in /usr/lib/x86_64-linux-gnu/libpython3.9.so.1.0)
==34772==    by 0x492BC7C: _PyFunction_Vectorcall (in /usr/lib/x86_64-linux-gnu/libpython3.9.so.1.0)
==34772==    by 0x48E0115: _PyEval_EvalFrameDefault (in /usr/lib/x86_64-linux-gnu/libpython3.9.so.1.0)
==34772==    by 0x4A0EDDB: ??? (in /usr/lib/x86_64-linux-gnu/libpython3.9.so.1.0)
==34772==    by 0x492BC7C: _PyFunction_Vectorcall (in /usr/lib/x86_64-linux-gnu/libpython3.9.so.1.0)
==34772==    by 0x48E14B6: _PyEval_EvalFrameDefault (in /usr/lib/x86_64-linux-gnu/libpython3.9.so.1.0)
==34772==    by 0x4A0EDDB: ??? (in /usr/lib/x86_64-linux-gnu/libpython3.9.so.1.0)
==34772==    by 0x492BC7C: _PyFunction_Vectorcall (in /usr/lib/x86_64-linux-gnu/libpython3.9.so.1.0)
==34772==    by 0x48DFC4C: _PyEval_EvalFrameDefault (in /usr/lib/x86_64-linux-gnu/libpython3.9.so.1.0)
==34772==
==34772== 584 bytes in 1 blocks are possibly lost in loss record 32,254 of 35,156
==34772==    at 0x483877F: malloc (vg_replace_malloc.c:307)
==34772==    by 0x49809C7: ??? (in /usr/lib/x86_64-linux-gnu/libpython3.9.so.1.0)
==34772==    by 0x4980ABF: ??? (in /usr/lib/x86_64-linux-gnu/libpython3.9.so.1.0)
==34772==    by 0x4A6E0D4: _PyObject_GC_Resize (in /usr/lib/x86_64-linux-gnu/libpython3.9.so.1.0)
==34772==    by 0x48E3568: ??? (in /usr/lib/x86_64-linux-gnu/libpython3.9.so.1.0)
==34772==    by 0x4A0E565: ??? (in /usr/lib/x86_64-linux-gnu/libpython3.9.so.1.0)
==34772==    by 0x492BC7C: _PyFunction_Vectorcall (in /usr/lib/x86_64-linux-gnu/libpython3.9.so.1.0)
==34772==    by 0x48DFC4C: _PyEval_EvalFrameDefault (in /usr/lib/x86_64-linux-gnu/libpython3.9.so.1.0)
==34772==    by 0x4A0EDDB: ??? (in /usr/lib/x86_64-linux-gnu/libpython3.9.so.1.0)
==34772==    by 0x492BC7C: _PyFunction_Vectorcall (in /usr/lib/x86_64-linux-gnu/libpython3.9.so.1.0)
==34772==    by 0x48E1584: _PyEval_EvalFrameDefault (in /usr/lib/x86_64-linux-gnu/libpython3.9.so.1.0)
==34772==    by 0x4A0EDDB: ??? (in /usr/lib/x86_64-linux-gnu/libpython3.9.so.1.0)
==34772==
==34772== 600 bytes in 1 blocks are possibly lost in loss record 32,260 of 35,156
==34772==    at 0x483877F: malloc (vg_replace_malloc.c:307)
==34772==    by 0x49809C7: ??? (in /usr/lib/x86_64-linux-gnu/libpython3.9.so.1.0)
==34772==    by 0x4A72244: _PyObject_GC_Malloc (in /usr/lib/x86_64-linux-gnu/libpython3.9.so.1.0)
==34772==    by 0x4A72567: _PyObject_GC_NewVar (in /usr/lib/x86_64-linux-gnu/libpython3.9.so.1.0)
==34772==    by 0x48E3750: ??? (in /usr/lib/x86_64-linux-gnu/libpython3.9.so.1.0)
==34772==    by 0x4A0E565: ??? (in /usr/lib/x86_64-linux-gnu/libpython3.9.so.1.0)
==34772==    by 0x492BC7C: _PyFunction_Vectorcall (in /usr/lib/x86_64-linux-gnu/libpython3.9.so.1.0)
==34772==    by 0x48DFC4C: _PyEval_EvalFrameDefault (in /usr/lib/x86_64-linux-gnu/libpython3.9.so.1.0)
==34772==    by 0x4A0EDDB: ??? (in /usr/lib/x86_64-linux-gnu/libpython3.9.so.1.0)
==34772==    by 0x492BC7C: _PyFunction_Vectorcall (in /usr/lib/x86_64-linux-gnu/libpython3.9.so.1.0)
==34772==    by 0x4933727: ??? (in /usr/lib/x86_64-linux-gnu/libpython3.9.so.1.0)
==34772==    by 0x48DFC4C: _PyEval_EvalFrameDefault (in /usr/lib/x86_64-linux-gnu/libpython3.9.so.1.0)
==34772==
==34772== 600 bytes in 1 blocks are possibly lost in loss record 32,261 of 35,156
==34772==    at 0x483877F: malloc (vg_replace_malloc.c:307)
==34772==    by 0x49809C7: ??? (in /usr/lib/x86_64-linux-gnu/libpython3.9.so.1.0)
==34772==    by 0x4A72244: _PyObject_GC_Malloc (in /usr/lib/x86_64-linux-gnu/libpython3.9.so.1.0)
==34772==    by 0x4A72567: _PyObject_GC_NewVar (in /usr/lib/x86_64-linux-gnu/libpython3.9.so.1.0)
==34772==    by 0x48E3750: ??? (in /usr/lib/x86_64-linux-gnu/libpython3.9.so.1.0)
==34772==    by 0x48D8FF0: ??? (in /usr/lib/x86_64-linux-gnu/libpython3.9.so.1.0)
==34772==    by 0x48E14B6: _PyEval_EvalFrameDefault (in /usr/lib/x86_64-linux-gnu/libpython3.9.so.1.0)
==34772==    by 0x48D9032: ??? (in /usr/lib/x86_64-linux-gnu/libpython3.9.so.1.0)
==34772==    by 0x4932F22: _PyObject_FastCallDictTstate (in /usr/lib/x86_64-linux-gnu/libpython3.9.so.1.0)
==34772==    by 0x493313F: _PyObject_Call_Prepend (in /usr/lib/x86_64-linux-gnu/libpython3.9.so.1.0)
==34772==    by 0x49996F1: ??? (in /usr/lib/x86_64-linux-gnu/libpython3.9.so.1.0)
==34772==    by 0x498E939: ??? (in /usr/lib/x86_64-linux-gnu/libpython3.9.so.1.0)
==34772==
==34772== 608 bytes in 1 blocks are possibly lost in loss record 32,272 of 35,156
==34772==    at 0x483877F: malloc (vg_replace_malloc.c:307)
==34772==    by 0x49809C7: ??? (in /usr/lib/x86_64-linux-gnu/libpython3.9.so.1.0)
==34772==    by 0x4A72244: _PyObject_GC_Malloc (in /usr/lib/x86_64-linux-gnu/libpython3.9.so.1.0)
==34772==    by 0x4A72567: _PyObject_GC_NewVar (in /usr/lib/x86_64-linux-gnu/libpython3.9.so.1.0)
==34772==    by 0x4989DC1: PyTuple_New (in /usr/lib/x86_64-linux-gnu/libpython3.9.so.1.0)
==34772==    by 0x4A3F1A7: ??? (in /usr/lib/x86_64-linux-gnu/libpython3.9.so.1.0)
==34772==    by 0x4A3FBE1: ??? (in /usr/lib/x86_64-linux-gnu/libpython3.9.so.1.0)
==34772==    by 0x4A3F1D0: ??? (in /usr/lib/x86_64-linux-gnu/libpython3.9.so.1.0)
==34772==    by 0x4A3FBCB: ??? (in /usr/lib/x86_64-linux-gnu/libpython3.9.so.1.0)
==34772==    by 0x4A3F1D0: ??? (in /usr/lib/x86_64-linux-gnu/libpython3.9.so.1.0)
==34772==    by 0x4A3FBCB: ??? (in /usr/lib/x86_64-linux-gnu/libpython3.9.so.1.0)
==34772==    by 0x4A40C1F: ??? (in /usr/lib/x86_64-linux-gnu/libpython3.9.so.1.0)
==34772==
==34772== 608 bytes in 1 blocks are possibly lost in loss record 32,273 of 35,156
==34772==    at 0x483877F: malloc (vg_replace_malloc.c:307)
==34772==    by 0x49809C7: ??? (in /usr/lib/x86_64-linux-gnu/libpython3.9.so.1.0)
==34772==    by 0x4980ABF: ??? (in /usr/lib/x86_64-linux-gnu/libpython3.9.so.1.0)
==34772==    by 0x4A6E0D4: _PyObject_GC_Resize (in /usr/lib/x86_64-linux-gnu/libpython3.9.so.1.0)
==34772==    by 0x48E3568: ??? (in /usr/lib/x86_64-linux-gnu/libpython3.9.so.1.0)
==34772==    by 0x4A0E565: ??? (in /usr/lib/x86_64-linux-gnu/libpython3.9.so.1.0)
==34772==    by 0x4A0F12D: _PyEval_EvalCodeWithName (in /usr/lib/x86_64-linux-gnu/libpython3.9.so.1.0)
==34772==    by 0x4A0F17D: PyEval_EvalCodeEx (in /usr/lib/x86_64-linux-gnu/libpython3.9.so.1.0)
==34772==    by 0x4A0AC52: ??? (in /usr/lib/x86_64-linux-gnu/libpython3.9.so.1.0)
==34772==    by 0x49770F8: ??? (in /usr/lib/x86_64-linux-gnu/libpython3.9.so.1.0)
==34772==    by 0x48E0115: _PyEval_EvalFrameDefault (in /usr/lib/x86_64-linux-gnu/libpython3.9.so.1.0)
==34772==    by 0x4A0EDDB: ??? (in /usr/lib/x86_64-linux-gnu/libpython3.9.so.1.0)
==34772==
==34772== 616 bytes in 1 blocks are possibly lost in loss record 32,274 of 35,156
==34772==    at 0x483AD7B: realloc (vg_replace_malloc.c:834)
==34772==    by 0x4A6E0D4: _PyObject_GC_Resize (in /usr/lib/x86_64-linux-gnu/libpython3.9.so.1.0)
==34772==    by 0x48E3568: ??? (in /usr/lib/x86_64-linux-gnu/libpython3.9.so.1.0)
==34772==    by 0x48D8FF0: ??? (in /usr/lib/x86_64-linux-gnu/libpython3.9.so.1.0)
==34772==    by 0x48E0115: _PyEval_EvalFrameDefault (in /usr/lib/x86_64-linux-gnu/libpython3.9.so.1.0)
==34772==    by 0x4A0EDDB: ??? (in /usr/lib/x86_64-linux-gnu/libpython3.9.so.1.0)
==34772==    by 0x492BC7C: _PyFunction_Vectorcall (in /usr/lib/x86_64-linux-gnu/libpython3.9.so.1.0)
==34772==    by 0x48E1584: _PyEval_EvalFrameDefault (in /usr/lib/x86_64-linux-gnu/libpython3.9.so.1.0)
==34772==    by 0x4A0EDDB: ??? (in /usr/lib/x86_64-linux-gnu/libpython3.9.so.1.0)
==34772==    by 0x4A0F12D: _PyEval_EvalCodeWithName (in /usr/lib/x86_64-linux-gnu/libpython3.9.so.1.0)
==34772==    by 0x4A0F17D: PyEval_EvalCodeEx (in /usr/lib/x86_64-linux-gnu/libpython3.9.so.1.0)
==34772==    by 0x4A0A72A: PyEval_EvalCode (in /usr/lib/x86_64-linux-gnu/libpython3.9.so.1.0)
==34772==
==34772== 632 bytes in 1 blocks are possibly lost in loss record 32,281 of 35,156
==34772==    at 0x483877F: malloc (vg_replace_malloc.c:307)
==34772==    by 0x49809C7: ??? (in /usr/lib/x86_64-linux-gnu/libpython3.9.so.1.0)
==34772==    by 0x4A72244: _PyObject_GC_Malloc (in /usr/lib/x86_64-linux-gnu/libpython3.9.so.1.0)
==34772==    by 0x4A72567: _PyObject_GC_NewVar (in /usr/lib/x86_64-linux-gnu/libpython3.9.so.1.0)
==34772==    by 0x48E3750: ??? (in /usr/lib/x86_64-linux-gnu/libpython3.9.so.1.0)
==34772==    by 0x4A0E565: ??? (in /usr/lib/x86_64-linux-gnu/libpython3.9.so.1.0)
==34772==    by 0x4A0F12D: _PyEval_EvalCodeWithName (in /usr/lib/x86_64-linux-gnu/libpython3.9.so.1.0)
==34772==    by 0x4A0F17D: PyEval_EvalCodeEx (in /usr/lib/x86_64-linux-gnu/libpython3.9.so.1.0)
==34772==    by 0x4A0AC52: ??? (in /usr/lib/x86_64-linux-gnu/libpython3.9.so.1.0)
==34772==    by 0x49770F8: ??? (in /usr/lib/x86_64-linux-gnu/libpython3.9.so.1.0)
==34772==    by 0x48E0115: _PyEval_EvalFrameDefault (in /usr/lib/x86_64-linux-gnu/libpython3.9.so.1.0)
==34772==    by 0x4A0EDDB: ??? (in /usr/lib/x86_64-linux-gnu/libpython3.9.so.1.0)
==34772==
==34772== 640 bytes in 16 blocks are definitely lost in loss record 32,367 of 35,156
==34772==    at 0x4838DEF: operator new(unsigned long) (vg_replace_malloc.c:342)
==34772==    by 0x64182E: gem5::X86ISA::ISA::newPCState(unsigned long) const (isa.hh:68)
==34772==    by 0xFEFB6F: gem5::SimpleThread::clearArchRegs() (simple_thread.hh:247)
==34772==    by 0xFEE597: gem5::SimpleThread::SimpleThread(gem5::BaseCPU*, int, gem5::System*, gem5::Process*, gem5::BaseMMU*, gem5::BaseISA*, gem5::InstDecoder*) (simple_thread.cc:87)
==34772==    by 0x1041C06: gem5::BaseSimpleCPU::BaseSimpleCPU(gem5::BaseSimpleCPUParams const&) (base.cc:99)
==34772==    by 0x10327F1: gem5::TimingSimpleCPU::TimingSimpleCPU(gem5::BaseTimingSimpleCPUParams const&) (timing.cc:79)
==34772==    by 0x1030022: gem5::(anonymous namespace)::DummyBaseTimingSimpleCPUShunt<gem5::TimingSimpleCPU, void>::create(gem5::BaseTimingSimpleCPUParams const&) (param_BaseTimingSimpleCPU.cc:76)
==34772==    by 0x102FFF5: gem5::BaseTimingSimpleCPUParams::create() const (param_BaseTimingSimpleCPU.cc:109)
==34772==    by 0x1030DD0: pybind11::cpp_function::cpp_function<gem5::TimingSimpleCPU*, gem5::BaseTimingSimpleCPUParams, , pybind11::name, pybind11::is_method, pybind11::sibling>(gem5::TimingSimpleCPU* (gem5::BaseTimingSimpleCPUParams::*)() const, pybind11::name const&, pybind11::is_method const&, pybind11::sibling const&)::{lambda(gem5::BaseTimingSimpleCPUParams const*)#1}::operator()(gem5::BaseTimingSimpleCPUParams const*) const (pybind11.h:132)
==34772==    by 0x1032062: gem5::TimingSimpleCPU* pybind11::detail::argument_loader<gem5::BaseTimingSimpleCPUParams const*>::call_impl<gem5::TimingSimpleCPU*, pybind11::cpp_function::cpp_function<gem5::TimingSimpleCPU*, gem5::BaseTimingSimpleCPUParams, , pybind11::name, pybind11::is_method, pybind11::sibling>(gem5::TimingSimpleCPU* (gem5::BaseTimingSimpleCPUParams::*)() const, pybind11::name const&, pybind11::is_method const&, pybind11::sibling const&)::{lambda(gem5::BaseTimingSimpleCPUParams const*)#1}&, 0ul, pybind11::detail::void_type>(pybind11::cpp_function::cpp_function<gem5::TimingSimpleCPU*, gem5::BaseTimingSimpleCPUParams, , pybind11::name, pybind11::is_method, pybind11::sibling>(gem5::TimingSimpleCPU* (gem5::BaseTimingSimpleCPUParams::*)() const, pybind11::name const&, pybind11::is_method const&, pybind11::sibling const&)::{lambda(gem5::BaseTimingSimpleCPUParams const*)#1}&, std::integer_sequence<unsigned long, 0ul>, pybind11::detail::void_type&&) && (cast.h:1443)
==34772==    by 0x1031A3A: std::enable_if<!std::is_void<gem5::TimingSimpleCPU*>::value, gem5::TimingSimpleCPU*>::type pybind11::detail::argument_loader<gem5::BaseTimingSimpleCPUParams const*>::call<gem5::TimingSimpleCPU*, pybind11::detail::void_type, pybind11::cpp_function::cpp_function<gem5::TimingSimpleCPU*, gem5::BaseTimingSimpleCPUParams, , pybind11::name, pybind11::is_method, pybind11::sibling>(gem5::TimingSimpleCPU* (gem5::BaseTimingSimpleCPUParams::*)() const, pybind11::name const&, pybind11::is_method const&, pybind11::sibling const&)::{lambda(gem5::BaseTimingSimpleCPUParams const*)#1}&>(pybind11::cpp_function::cpp_function<gem5::TimingSimpleCPU*, gem5::BaseTimingSimpleCPUParams, , pybind11::name, pybind11::is_method, pybind11::sibling>(gem5::TimingSimpleCPU* (gem5::BaseTimingSimpleCPUParams::*)() const, pybind11::name const&, pybind11::is_method const&, pybind11::sibling const&)::{lambda(gem5::BaseTimingSimpleCPUParams const*)#1}&) && (cast.h:1411)
==34772==    by 0x10313ED: void pybind11::cpp_function::initialize<pybind11::cpp_function::initialize<gem5::TimingSimpleCPU*, gem5::BaseTimingSimpleCPUParams, , pybind11::name, pybind11::is_method, pybind11::sibling>(gem5::TimingSimpleCPU* (gem5::BaseTimingSimpleCPUParams::*)() const, pybind11::name const&, pybind11::is_method const&, pybind11::sibling const&)::{lambda(gem5::BaseTimingSimpleCPUParams const*)#1}, gem5::TimingSimpleCPU*, gem5::BaseTimingSimpleCPUParams const*, pybind11::name, pybind11::is_method, pybind11::sibling>(pybind11::cpp_function::initialize<gem5::TimingSimpleCPU*, gem5::BaseTimingSimpleCPUParams, , pybind11::name, pybind11::is_method, pybind11::sibling>(gem5::TimingSimpleCPU* (gem5::BaseTimingSimpleCPUParams::*)() const, pybind11::name const&, pybind11::is_method const&, pybind11::sibling const&)::{lambda(gem5::BaseTimingSimpleCPUParams const*)#1}&&, gem5::TimingSimpleCPU* (*)(gem5::BaseTimingSimpleCPUParams const*), pybind11::name const&, pybind11::is_method const&, pybind11::sibling const&)::{lambda(pybind11::detail::function_call&)#3}::operator()(pybind11::detail::function_call) const (pybind11.h:248)
==34772==
==34772== 672 bytes in 1 blocks are possibly lost in loss record 32,387 of 35,156
==34772==    at 0x483877F: malloc (vg_replace_malloc.c:307)
==34772==    by 0x49809C7: ??? (in /usr/lib/x86_64-linux-gnu/libpython3.9.so.1.0)
==34772==    by 0x4A72244: _PyObject_GC_Malloc (in /usr/lib/x86_64-linux-gnu/libpython3.9.so.1.0)
==34772==    by 0x4A72567: _PyObject_GC_NewVar (in /usr/lib/x86_64-linux-gnu/libpython3.9.so.1.0)
==34772==    by 0x48E3750: ??? (in /usr/lib/x86_64-linux-gnu/libpython3.9.so.1.0)
==34772==    by 0x48D8FF0: ??? (in /usr/lib/x86_64-linux-gnu/libpython3.9.so.1.0)
==34772==    by 0x48E0115: _PyEval_EvalFrameDefault (in /usr/lib/x86_64-linux-gnu/libpython3.9.so.1.0)
==34772==    by 0x48D9032: ??? (in /usr/lib/x86_64-linux-gnu/libpython3.9.so.1.0)
==34772==    by 0x48E0115: _PyEval_EvalFrameDefault (in /usr/lib/x86_64-linux-gnu/libpython3.9.so.1.0)
==34772==    by 0x48D9032: ??? (in /usr/lib/x86_64-linux-gnu/libpython3.9.so.1.0)
==34772==    by 0x48E0115: _PyEval_EvalFrameDefault (in /usr/lib/x86_64-linux-gnu/libpython3.9.so.1.0)
==34772==    by 0x4A0EDDB: ??? (in /usr/lib/x86_64-linux-gnu/libpython3.9.so.1.0)
==34772==
==34772== 672 bytes in 1 blocks are possibly lost in loss record 32,388 of 35,156
==34772==    at 0x483AD7B: realloc (vg_replace_malloc.c:834)
==34772==    by 0x4A6E0D4: _PyObject_GC_Resize (in /usr/lib/x86_64-linux-gnu/libpython3.9.so.1.0)
==34772==    by 0x48E3568: ??? (in /usr/lib/x86_64-linux-gnu/libpython3.9.so.1.0)
==34772==    by 0x48D8FF0: ??? (in /usr/lib/x86_64-linux-gnu/libpython3.9.so.1.0)
==34772==    by 0x48E0115: _PyEval_EvalFrameDefault (in /usr/lib/x86_64-linux-gnu/libpython3.9.so.1.0)
==34772==    by 0x48D9032: ??? (in /usr/lib/x86_64-linux-gnu/libpython3.9.so.1.0)
==34772==    by 0x48E0115: _PyEval_EvalFrameDefault (in /usr/lib/x86_64-linux-gnu/libpython3.9.so.1.0)
==34772==    by 0x48D9032: ??? (in /usr/lib/x86_64-linux-gnu/libpython3.9.so.1.0)
==34772==    by 0x48E0115: _PyEval_EvalFrameDefault (in /usr/lib/x86_64-linux-gnu/libpython3.9.so.1.0)
==34772==    by 0x48D9032: ??? (in /usr/lib/x86_64-linux-gnu/libpython3.9.so.1.0)
==34772==    by 0x48E0115: _PyEval_EvalFrameDefault (in /usr/lib/x86_64-linux-gnu/libpython3.9.so.1.0)
==34772==    by 0x4A0EDDB: ??? (in /usr/lib/x86_64-linux-gnu/libpython3.9.so.1.0)
==34772==
==34772== 672 bytes in 1 blocks are possibly lost in loss record 32,389 of 35,156
==34772==    at 0x483AD7B: realloc (vg_replace_malloc.c:834)
==34772==    by 0x4A6E0D4: _PyObject_GC_Resize (in /usr/lib/x86_64-linux-gnu/libpython3.9.so.1.0)
==34772==    by 0x48E3568: ??? (in /usr/lib/x86_64-linux-gnu/libpython3.9.so.1.0)
==34772==    by 0x48D8FF0: ??? (in /usr/lib/x86_64-linux-gnu/libpython3.9.so.1.0)
==34772==    by 0x48E0115: _PyEval_EvalFrameDefault (in /usr/lib/x86_64-linux-gnu/libpython3.9.so.1.0)
==34772==    by 0x48D9032: ??? (in /usr/lib/x86_64-linux-gnu/libpython3.9.so.1.0)
==34772==    by 0x48E0115: _PyEval_EvalFrameDefault (in /usr/lib/x86_64-linux-gnu/libpython3.9.so.1.0)
==34772==    by 0x48D9032: ??? (in /usr/lib/x86_64-linux-gnu/libpython3.9.so.1.0)
==34772==    by 0x48E0115: _PyEval_EvalFrameDefault (in /usr/lib/x86_64-linux-gnu/libpython3.9.so.1.0)
==34772==    by 0x48D9032: ??? (in /usr/lib/x86_64-linux-gnu/libpython3.9.so.1.0)
==34772==    by 0x48E0115: _PyEval_EvalFrameDefault (in /usr/lib/x86_64-linux-gnu/libpython3.9.so.1.0)
==34772==    by 0x48D9032: ??? (in /usr/lib/x86_64-linux-gnu/libpython3.9.so.1.0)
==34772==
==34772== 672 bytes in 1 blocks are possibly lost in loss record 32,390 of 35,156
==34772==    at 0x483877F: malloc (vg_replace_malloc.c:307)
==34772==    by 0x49809C7: ??? (in /usr/lib/x86_64-linux-gnu/libpython3.9.so.1.0)
==34772==    by 0x4980ABF: ??? (in /usr/lib/x86_64-linux-gnu/libpython3.9.so.1.0)
==34772==    by 0x4A6E0D4: _PyObject_GC_Resize (in /usr/lib/x86_64-linux-gnu/libpython3.9.so.1.0)
==34772==    by 0x48E3568: ??? (in /usr/lib/x86_64-linux-gnu/libpython3.9.so.1.0)
==34772==    by 0x4A0E565: ??? (in /usr/lib/x86_64-linux-gnu/libpython3.9.so.1.0)
==34772==    by 0x492BC7C: _PyFunction_Vectorcall (in /usr/lib/x86_64-linux-gnu/libpython3.9.so.1.0)
==34772==    by 0x48E0115: _PyEval_EvalFrameDefault (in /usr/lib/x86_64-linux-gnu/libpython3.9.so.1.0)
==34772==    by 0x4946BEB: ??? (in /usr/lib/x86_64-linux-gnu/libpython3.9.so.1.0)
==34772==    by 0x48DD4E5: _PyEval_EvalFrameDefault (in /usr/lib/x86_64-linux-gnu/libpython3.9.so.1.0)
==34772==    by 0x4A0EDDB: ??? (in /usr/lib/x86_64-linux-gnu/libpython3.9.so.1.0)
==34772==    by 0x492BC7C: _PyFunction_Vectorcall (in /usr/lib/x86_64-linux-gnu/libpython3.9.so.1.0)
==34772==
==34772== 672 bytes in 1 blocks are possibly lost in loss record 32,391 of 35,156
==34772==    at 0x483877F: malloc (vg_replace_malloc.c:307)
==34772==    by 0x49809C7: ??? (in /usr/lib/x86_64-linux-gnu/libpython3.9.so.1.0)
==34772==    by 0x4980ABF: ??? (in /usr/lib/x86_64-linux-gnu/libpython3.9.so.1.0)
==34772==    by 0x4A6E0D4: _PyObject_GC_Resize (in /usr/lib/x86_64-linux-gnu/libpython3.9.so.1.0)
==34772==    by 0x48E3568: ??? (in /usr/lib/x86_64-linux-gnu/libpython3.9.so.1.0)
==34772==    by 0x4A0E565: ??? (in /usr/lib/x86_64-linux-gnu/libpython3.9.so.1.0)
==34772==    by 0x492BC7C: _PyFunction_Vectorcall (in /usr/lib/x86_64-linux-gnu/libpython3.9.so.1.0)
==34772==    by 0x48E0115: _PyEval_EvalFrameDefault (in /usr/lib/x86_64-linux-gnu/libpython3.9.so.1.0)
==34772==    by 0x4945C8E: ??? (in /usr/lib/x86_64-linux-gnu/libpython3.9.so.1.0)
==34772==    by 0x48DFBD4: _PyEval_EvalFrameDefault (in /usr/lib/x86_64-linux-gnu/libpython3.9.so.1.0)
==34772==    by 0x4946BEB: ??? (in /usr/lib/x86_64-linux-gnu/libpython3.9.so.1.0)
==34772==    by 0x48DD4E5: _PyEval_EvalFrameDefault (in /usr/lib/x86_64-linux-gnu/libpython3.9.so.1.0)
==34772==
==34772== 696 bytes in 1 blocks are possibly lost in loss record 32,399 of 35,156
==34772==    at 0x483877F: malloc (vg_replace_malloc.c:307)
==34772==    by 0x49809C7: ??? (in /usr/lib/x86_64-linux-gnu/libpython3.9.so.1.0)
==34772==    by 0x4980ABF: ??? (in /usr/lib/x86_64-linux-gnu/libpython3.9.so.1.0)
==34772==    by 0x4A6E0D4: _PyObject_GC_Resize (in /usr/lib/x86_64-linux-gnu/libpython3.9.so.1.0)
==34772==    by 0x48E3568: ??? (in /usr/lib/x86_64-linux-gnu/libpython3.9.so.1.0)
==34772==    by 0x4A0E565: ??? (in /usr/lib/x86_64-linux-gnu/libpython3.9.so.1.0)
==34772==    by 0x4A0F12D: _PyEval_EvalCodeWithName (in /usr/lib/x86_64-linux-gnu/libpython3.9.so.1.0)
==34772==    by 0x4A0F17D: PyEval_EvalCodeEx (in /usr/lib/x86_64-linux-gnu/libpython3.9.so.1.0)
==34772==    by 0x4A0A72A: PyEval_EvalCode (in /usr/lib/x86_64-linux-gnu/libpython3.9.so.1.0)
==34772==    by 0x4A092A0: ??? (in /usr/lib/x86_64-linux-gnu/libpython3.9.so.1.0)
==34772==    by 0x497BE83: ??? (in /usr/lib/x86_64-linux-gnu/libpython3.9.so.1.0)
==34772==    by 0x48E0115: _PyEval_EvalFrameDefault (in /usr/lib/x86_64-linux-gnu/libpython3.9.so.1.0)
==34772==
==34772== 720 bytes in 1 blocks are possibly lost in loss record 32,421 of 35,156
==34772==    at 0x483877F: malloc (vg_replace_malloc.c:307)
==34772==    by 0x49809C7: ??? (in /usr/lib/x86_64-linux-gnu/libpython3.9.so.1.0)
==34772==    by 0x4A72244: _PyObject_GC_Malloc (in /usr/lib/x86_64-linux-gnu/libpython3.9.so.1.0)
==34772==    by 0x4A72567: _PyObject_GC_NewVar (in /usr/lib/x86_64-linux-gnu/libpython3.9.so.1.0)
==34772==    by 0x48E3750: ??? (in /usr/lib/x86_64-linux-gnu/libpython3.9.so.1.0)
==34772==    by 0x4A0E565: ??? (in /usr/lib/x86_64-linux-gnu/libpython3.9.so.1.0)
==34772==    by 0x492BC7C: _PyFunction_Vectorcall (in /usr/lib/x86_64-linux-gnu/libpython3.9.so.1.0)
==34772==    by 0x48E0115: _PyEval_EvalFrameDefault (in /usr/lib/x86_64-linux-gnu/libpython3.9.so.1.0)
==34772==    by 0x4A0EDDB: ??? (in /usr/lib/x86_64-linux-gnu/libpython3.9.so.1.0)
==34772==    by 0x4A0F12D: _PyEval_EvalCodeWithName (in /usr/lib/x86_64-linux-gnu/libpython3.9.so.1.0)
==34772==    by 0x4A0F17D: PyEval_EvalCodeEx (in /usr/lib/x86_64-linux-gnu/libpython3.9.so.1.0)
==34772==    by 0x4A0A72A: PyEval_EvalCode (in /usr/lib/x86_64-linux-gnu/libpython3.9.so.1.0)
==34772==
==34772== 744 bytes in 1 blocks are possibly lost in loss record 32,427 of 35,156
==34772==    at 0x483877F: malloc (vg_replace_malloc.c:307)
==34772==    by 0x49809C7: ??? (in /usr/lib/x86_64-linux-gnu/libpython3.9.so.1.0)
==34772==    by 0x4A72244: _PyObject_GC_Malloc (in /usr/lib/x86_64-linux-gnu/libpython3.9.so.1.0)
==34772==    by 0x4A72567: _PyObject_GC_NewVar (in /usr/lib/x86_64-linux-gnu/libpython3.9.so.1.0)
==34772==    by 0x48E3750: ??? (in /usr/lib/x86_64-linux-gnu/libpython3.9.so.1.0)
==34772==    by 0x4A0E565: ??? (in /usr/lib/x86_64-linux-gnu/libpython3.9.so.1.0)
==34772==    by 0x492BC7C: _PyFunction_Vectorcall (in /usr/lib/x86_64-linux-gnu/libpython3.9.so.1.0)
==34772==    by 0x48E14B6: _PyEval_EvalFrameDefault (in /usr/lib/x86_64-linux-gnu/libpython3.9.so.1.0)
==34772==    by 0x4A0EDDB: ??? (in /usr/lib/x86_64-linux-gnu/libpython3.9.so.1.0)
==34772==    by 0x492BC7C: _PyFunction_Vectorcall (in /usr/lib/x86_64-linux-gnu/libpython3.9.so.1.0)
==34772==    by 0x48E14B6: _PyEval_EvalFrameDefault (in /usr/lib/x86_64-linux-gnu/libpython3.9.so.1.0)
==34772==    by 0x4A0EDDB: ??? (in /usr/lib/x86_64-linux-gnu/libpython3.9.so.1.0)
==34772==
==34772== 760 bytes in 1 blocks are possibly lost in loss record 32,435 of 35,156
==34772==    at 0x483877F: malloc (vg_replace_malloc.c:307)
==34772==    by 0x49809C7: ??? (in /usr/lib/x86_64-linux-gnu/libpython3.9.so.1.0)
==34772==    by 0x4980ABF: ??? (in /usr/lib/x86_64-linux-gnu/libpython3.9.so.1.0)
==34772==    by 0x4A6E0D4: _PyObject_GC_Resize (in /usr/lib/x86_64-linux-gnu/libpython3.9.so.1.0)
==34772==    by 0x48E3568: ??? (in /usr/lib/x86_64-linux-gnu/libpython3.9.so.1.0)
==34772==    by 0x48D8FF0: ??? (in /usr/lib/x86_64-linux-gnu/libpython3.9.so.1.0)
==34772==    by 0x48E1584: _PyEval_EvalFrameDefault (in /usr/lib/x86_64-linux-gnu/libpython3.9.so.1.0)
==34772==    by 0x4A0EDDB: ??? (in /usr/lib/x86_64-linux-gnu/libpython3.9.so.1.0)
==34772==    by 0x4A0F12D: _PyEval_EvalCodeWithName (in /usr/lib/x86_64-linux-gnu/libpython3.9.so.1.0)
==34772==    by 0x4A0F17D: PyEval_EvalCodeEx (in /usr/lib/x86_64-linux-gnu/libpython3.9.so.1.0)
==34772==    by 0x4A0A72A: PyEval_EvalCode (in /usr/lib/x86_64-linux-gnu/libpython3.9.so.1.0)
==34772==    by 0x4A53734: ??? (in /usr/lib/x86_64-linux-gnu/libpython3.9.so.1.0)
==34772==
==34772== 784 bytes in 1 blocks are possibly lost in loss record 32,495 of 35,156
==34772==    at 0x483AD7B: realloc (vg_replace_malloc.c:834)
==34772==    by 0x4A6E0D4: _PyObject_GC_Resize (in /usr/lib/x86_64-linux-gnu/libpython3.9.so.1.0)
==34772==    by 0x48E3568: ??? (in /usr/lib/x86_64-linux-gnu/libpython3.9.so.1.0)
==34772==    by 0x4A0E565: ??? (in /usr/lib/x86_64-linux-gnu/libpython3.9.so.1.0)
==34772==    by 0x492BC7C: _PyFunction_Vectorcall (in /usr/lib/x86_64-linux-gnu/libpython3.9.so.1.0)
==34772==    by 0x48E14B6: _PyEval_EvalFrameDefault (in /usr/lib/x86_64-linux-gnu/libpython3.9.so.1.0)
==34772==    by 0x4A0EDDB: ??? (in /usr/lib/x86_64-linux-gnu/libpython3.9.so.1.0)
==34772==    by 0x492BC7C: _PyFunction_Vectorcall (in /usr/lib/x86_64-linux-gnu/libpython3.9.so.1.0)
==34772==    by 0x48E1584: _PyEval_EvalFrameDefault (in /usr/lib/x86_64-linux-gnu/libpython3.9.so.1.0)
==34772==    by 0x4A0EDDB: ??? (in /usr/lib/x86_64-linux-gnu/libpython3.9.so.1.0)
==34772==    by 0x4A0F12D: _PyEval_EvalCodeWithName (in /usr/lib/x86_64-linux-gnu/libpython3.9.so.1.0)
==34772==    by 0x4A0F17D: PyEval_EvalCodeEx (in /usr/lib/x86_64-linux-gnu/libpython3.9.so.1.0)
==34772==
==34772== 792 bytes in 1 blocks are possibly lost in loss record 32,500 of 35,156
==34772==    at 0x483877F: malloc (vg_replace_malloc.c:307)
==34772==    by 0x49809C7: ??? (in /usr/lib/x86_64-linux-gnu/libpython3.9.so.1.0)
==34772==    by 0x49A1322: PyUnicode_New (in /usr/lib/x86_64-linux-gnu/libpython3.9.so.1.0)
==34772==    by 0x49A45BD: ??? (in /usr/lib/x86_64-linux-gnu/libpython3.9.so.1.0)
==34772==    by 0x4A3ED6D: ??? (in /usr/lib/x86_64-linux-gnu/libpython3.9.so.1.0)
==34772==    by 0x4A3F1D0: ??? (in /usr/lib/x86_64-linux-gnu/libpython3.9.so.1.0)
==34772==    by 0x4A3FBCB: ??? (in /usr/lib/x86_64-linux-gnu/libpython3.9.so.1.0)
==34772==    by 0x4A3F1D0: ??? (in /usr/lib/x86_64-linux-gnu/libpython3.9.so.1.0)
==34772==    by 0x4A3FBCB: ??? (in /usr/lib/x86_64-linux-gnu/libpython3.9.so.1.0)
==34772==    by 0x4A40C1F: ??? (in /usr/lib/x86_64-linux-gnu/libpython3.9.so.1.0)
==34772==    by 0x497BD32: ??? (in /usr/lib/x86_64-linux-gnu/libpython3.9.so.1.0)
==34772==    by 0x3369BE: pybind11::detail::simple_collector<(pybind11::return_value_policy)1>::call(_object*) const (cast.h:1465)
==34772==
==34772== 824 bytes in 1 blocks are possibly lost in loss record 32,519 of 35,156
==34772==    at 0x483AD7B: realloc (vg_replace_malloc.c:834)
==34772==    by 0x4A6E0D4: _PyObject_GC_Resize (in /usr/lib/x86_64-linux-gnu/libpython3.9.so.1.0)
==34772==    by 0x48E3568: ??? (in /usr/lib/x86_64-linux-gnu/libpython3.9.so.1.0)
==34772==    by 0x4A0E565: ??? (in /usr/lib/x86_64-linux-gnu/libpython3.9.so.1.0)
==34772==    by 0x492BC7C: _PyFunction_Vectorcall (in /usr/lib/x86_64-linux-gnu/libpython3.9.so.1.0)
==34772==    by 0x48E0115: _PyEval_EvalFrameDefault (in /usr/lib/x86_64-linux-gnu/libpython3.9.so.1.0)
==34772==    by 0x4A0EDDB: ??? (in /usr/lib/x86_64-linux-gnu/libpython3.9.so.1.0)
==34772==    by 0x492BC7C: _PyFunction_Vectorcall (in /usr/lib/x86_64-linux-gnu/libpython3.9.so.1.0)
==34772==    by 0x4B46FD6: ??? (in /usr/lib/x86_64-linux-gnu/libpython3.9.so.1.0)
==34772==    by 0x4976C73: ??? (in /usr/lib/x86_64-linux-gnu/libpython3.9.so.1.0)
==34772==    by 0x4930A4F: _PyObject_MakeTpCall (in /usr/lib/x86_64-linux-gnu/libpython3.9.so.1.0)
==34772==    by 0x48E0F07: _PyEval_EvalFrameDefault (in /usr/lib/x86_64-linux-gnu/libpython3.9.so.1.0)
==34772==
==34772== 832 bytes in 1 blocks are possibly lost in loss record 32,523 of 35,156
==34772==    at 0x483877F: malloc (vg_replace_malloc.c:307)
==34772==    by 0x49809C7: ??? (in /usr/lib/x86_64-linux-gnu/libpython3.9.so.1.0)
==34772==    by 0x4980ABF: ??? (in /usr/lib/x86_64-linux-gnu/libpython3.9.so.1.0)
==34772==    by 0x4A6E0D4: _PyObject_GC_Resize (in /usr/lib/x86_64-linux-gnu/libpython3.9.so.1.0)
==34772==    by 0x48E3568: ??? (in /usr/lib/x86_64-linux-gnu/libpython3.9.so.1.0)
==34772==    by 0x48D8FF0: ??? (in /usr/lib/x86_64-linux-gnu/libpython3.9.so.1.0)
==34772==    by 0x3369BE: pybind11::detail::simple_collector<(pybind11::return_value_policy)1>::call(_object*) const (cast.h:1465)
==34772==    by 0xEB3D02: pybind11::object pybind11::detail::object_api<pybind11::detail::accessor<pybind11::detail::accessor_policies::str_attr> >::operator()<(pybind11::return_value_policy)1>() const (cast.h:1635)
==34772==    by 0xEB2B27: main (main.cc:69)
==34772==
==34772== 888 bytes in 1 blocks are possibly lost in loss record 32,535 of 35,156
==34772==    at 0x483877F: malloc (vg_replace_malloc.c:307)
==34772==    by 0x49809C7: ??? (in /usr/lib/x86_64-linux-gnu/libpython3.9.so.1.0)
==34772==    by 0x4980ABF: ??? (in /usr/lib/x86_64-linux-gnu/libpython3.9.so.1.0)
==34772==    by 0x4A6E0D4: _PyObject_GC_Resize (in /usr/lib/x86_64-linux-gnu/libpython3.9.so.1.0)
==34772==    by 0x48E3568: ??? (in /usr/lib/x86_64-linux-gnu/libpython3.9.so.1.0)
==34772==    by 0x4A0E565: ??? (in /usr/lib/x86_64-linux-gnu/libpython3.9.so.1.0)
==34772==    by 0x492BC7C: _PyFunction_Vectorcall (in /usr/lib/x86_64-linux-gnu/libpython3.9.so.1.0)
==34772==    by 0x48E0115: _PyEval_EvalFrameDefault (in /usr/lib/x86_64-linux-gnu/libpython3.9.so.1.0)
==34772==    by 0x4A0EDDB: ??? (in /usr/lib/x86_64-linux-gnu/libpython3.9.so.1.0)
==34772==    by 0x492BC7C: _PyFunction_Vectorcall (in /usr/lib/x86_64-linux-gnu/libpython3.9.so.1.0)
==34772==    by 0x48E14B6: _PyEval_EvalFrameDefault (in /usr/lib/x86_64-linux-gnu/libpython3.9.so.1.0)
==34772==    by 0x4A0EDDB: ??? (in /usr/lib/x86_64-linux-gnu/libpython3.9.so.1.0)
==34772==
==34772== 912 bytes in 1 blocks are possibly lost in loss record 32,554 of 35,156
==34772==    at 0x483877F: malloc (vg_replace_malloc.c:307)
==34772==    by 0x49809C7: ??? (in /usr/lib/x86_64-linux-gnu/libpython3.9.so.1.0)
==34772==    by 0x4A72244: _PyObject_GC_Malloc (in /usr/lib/x86_64-linux-gnu/libpython3.9.so.1.0)
==34772==    by 0x4A72567: _PyObject_GC_NewVar (in /usr/lib/x86_64-linux-gnu/libpython3.9.so.1.0)
==34772==    by 0x4989DC1: PyTuple_New (in /usr/lib/x86_64-linux-gnu/libpython3.9.so.1.0)
==34772==    by 0x4A3F1A7: ??? (in /usr/lib/x86_64-linux-gnu/libpython3.9.so.1.0)
==34772==    by 0x4A3FBE1: ??? (in /usr/lib/x86_64-linux-gnu/libpython3.9.so.1.0)
==34772==    by 0x4A40C1F: ??? (in /usr/lib/x86_64-linux-gnu/libpython3.9.so.1.0)
==34772==    by 0x497BD32: ??? (in /usr/lib/x86_64-linux-gnu/libpython3.9.so.1.0)
==34772==    by 0x3369BE: pybind11::detail::simple_collector<(pybind11::return_value_policy)1>::call(_object*) const (cast.h:1465)
==34772==    by 0x13E5D68: pybind11::object pybind11::detail::object_api<pybind11::detail::accessor<pybind11::detail::accessor_policies::str_attr> >::operator()<(pybind11::return_value_policy)1, pybind11::bytes>(pybind11::bytes&&) const (cast.h:1635)
==34772==    by 0x13E55AB: gem5::EmbeddedPython::getCode() const (embedded.cc:88)
==34772==
==34772== 1,072 bytes in 2 blocks are possibly lost in loss record 33,708 of 35,156
==34772==    at 0x483877F: malloc (vg_replace_malloc.c:307)
==34772==    by 0x49809C7: ??? (in /usr/lib/x86_64-linux-gnu/libpython3.9.so.1.0)
==34772==    by 0x4A72244: _PyObject_GC_Malloc (in /usr/lib/x86_64-linux-gnu/libpython3.9.so.1.0)
==34772==    by 0x4A72567: _PyObject_GC_NewVar (in /usr/lib/x86_64-linux-gnu/libpython3.9.so.1.0)
==34772==    by 0x48E3750: ??? (in /usr/lib/x86_64-linux-gnu/libpython3.9.so.1.0)
==34772==    by 0x48D8FF0: ??? (in /usr/lib/x86_64-linux-gnu/libpython3.9.so.1.0)
==34772==    by 0x4933727: ??? (in /usr/lib/x86_64-linux-gnu/libpython3.9.so.1.0)
==34772==    by 0x48E1584: _PyEval_EvalFrameDefault (in /usr/lib/x86_64-linux-gnu/libpython3.9.so.1.0)
==34772==    by 0x48D9032: ??? (in /usr/lib/x86_64-linux-gnu/libpython3.9.so.1.0)
==34772==    by 0x4933727: ??? (in /usr/lib/x86_64-linux-gnu/libpython3.9.so.1.0)
==34772==    by 0x48E1584: _PyEval_EvalFrameDefault (in /usr/lib/x86_64-linux-gnu/libpython3.9.so.1.0)
==34772==    by 0x48D9032: ??? (in /usr/lib/x86_64-linux-gnu/libpython3.9.so.1.0)
==34772==
==34772== 1,088 bytes in 1 blocks are possibly lost in loss record 33,711 of 35,156
==34772==    at 0x483877F: malloc (vg_replace_malloc.c:307)
==34772==    by 0x49809C7: ??? (in /usr/lib/x86_64-linux-gnu/libpython3.9.so.1.0)
==34772==    by 0x4A72244: _PyObject_GC_Malloc (in /usr/lib/x86_64-linux-gnu/libpython3.9.so.1.0)
==34772==    by 0x4A72567: _PyObject_GC_NewVar (in /usr/lib/x86_64-linux-gnu/libpython3.9.so.1.0)
==34772==    by 0x4989DC1: PyTuple_New (in /usr/lib/x86_64-linux-gnu/libpython3.9.so.1.0)
==34772==    by 0x4A245A6: ??? (in /usr/lib/x86_64-linux-gnu/libpython3.9.so.1.0)
==34772==    by 0x4A15B2D: PyAST_CompileObject (in /usr/lib/x86_64-linux-gnu/libpython3.9.so.1.0)
==34772==    by 0x4A5417A: Py_CompileStringObject (in /usr/lib/x86_64-linux-gnu/libpython3.9.so.1.0)
==34772==    by 0x4A07CD6: ??? (in /usr/lib/x86_64-linux-gnu/libpython3.9.so.1.0)
==34772==    by 0x49770F8: ??? (in /usr/lib/x86_64-linux-gnu/libpython3.9.so.1.0)
==34772==    by 0x48E0115: _PyEval_EvalFrameDefault (in /usr/lib/x86_64-linux-gnu/libpython3.9.so.1.0)
==34772==    by 0x48D9032: ??? (in /usr/lib/x86_64-linux-gnu/libpython3.9.so.1.0)
==34772==
==34772== 1,088 bytes in 2 blocks are possibly lost in loss record 33,712 of 35,156
==34772==    at 0x483877F: malloc (vg_replace_malloc.c:307)
==34772==    by 0x49809C7: ??? (in /usr/lib/x86_64-linux-gnu/libpython3.9.so.1.0)
==34772==    by 0x4A72244: _PyObject_GC_Malloc (in /usr/lib/x86_64-linux-gnu/libpython3.9.so.1.0)
==34772==    by 0x4A72567: _PyObject_GC_NewVar (in /usr/lib/x86_64-linux-gnu/libpython3.9.so.1.0)
==34772==    by 0x48E3750: ??? (in /usr/lib/x86_64-linux-gnu/libpython3.9.so.1.0)
==34772==    by 0x4A0E565: ??? (in /usr/lib/x86_64-linux-gnu/libpython3.9.so.1.0)
==34772==    by 0x492BC7C: _PyFunction_Vectorcall (in /usr/lib/x86_64-linux-gnu/libpython3.9.so.1.0)
==34772==    by 0x48DFC4C: _PyEval_EvalFrameDefault (in /usr/lib/x86_64-linux-gnu/libpython3.9.so.1.0)
==34772==    by 0x4A0EDDB: ??? (in /usr/lib/x86_64-linux-gnu/libpython3.9.so.1.0)
==34772==    by 0x492BC7C: _PyFunction_Vectorcall (in /usr/lib/x86_64-linux-gnu/libpython3.9.so.1.0)
==34772==    by 0x48E0115: _PyEval_EvalFrameDefault (in /usr/lib/x86_64-linux-gnu/libpython3.9.so.1.0)
==34772==    by 0x48D9032: ??? (in /usr/lib/x86_64-linux-gnu/libpython3.9.so.1.0)
==34772==
==34772== 1,128 bytes in 2 blocks are possibly lost in loss record 33,773 of 35,156
==34772==    at 0x483877F: malloc (vg_replace_malloc.c:307)
==34772==    by 0x49809C7: ??? (in /usr/lib/x86_64-linux-gnu/libpython3.9.so.1.0)
==34772==    by 0x4A72244: _PyObject_GC_Malloc (in /usr/lib/x86_64-linux-gnu/libpython3.9.so.1.0)
==34772==    by 0x4A72567: _PyObject_GC_NewVar (in /usr/lib/x86_64-linux-gnu/libpython3.9.so.1.0)
==34772==    by 0x48E3750: ??? (in /usr/lib/x86_64-linux-gnu/libpython3.9.so.1.0)
==34772==    by 0x4A0E565: ??? (in /usr/lib/x86_64-linux-gnu/libpython3.9.so.1.0)
==34772==    by 0x492BC7C: _PyFunction_Vectorcall (in /usr/lib/x86_64-linux-gnu/libpython3.9.so.1.0)
==34772==    by 0x48E0115: _PyEval_EvalFrameDefault (in /usr/lib/x86_64-linux-gnu/libpython3.9.so.1.0)
==34772==    by 0x4A0EDDB: ??? (in /usr/lib/x86_64-linux-gnu/libpython3.9.so.1.0)
==34772==    by 0x492BC7C: _PyFunction_Vectorcall (in /usr/lib/x86_64-linux-gnu/libpython3.9.so.1.0)
==34772==    by 0x48E14B6: _PyEval_EvalFrameDefault (in /usr/lib/x86_64-linux-gnu/libpython3.9.so.1.0)
==34772==    by 0x4A0EDDB: ??? (in /usr/lib/x86_64-linux-gnu/libpython3.9.so.1.0)
==34772==
==34772== 1,152 bytes in 2 blocks are possibly lost in loss record 33,823 of 35,156
==34772==    at 0x483877F: malloc (vg_replace_malloc.c:307)
==34772==    by 0x49809C7: ??? (in /usr/lib/x86_64-linux-gnu/libpython3.9.so.1.0)
==34772==    by 0x4A72244: _PyObject_GC_Malloc (in /usr/lib/x86_64-linux-gnu/libpython3.9.so.1.0)
==34772==    by 0x4A72567: _PyObject_GC_NewVar (in /usr/lib/x86_64-linux-gnu/libpython3.9.so.1.0)
==34772==    by 0x48E3750: ??? (in /usr/lib/x86_64-linux-gnu/libpython3.9.so.1.0)
==34772==    by 0x4A0E565: ??? (in /usr/lib/x86_64-linux-gnu/libpython3.9.so.1.0)
==34772==    by 0x492BC7C: _PyFunction_Vectorcall (in /usr/lib/x86_64-linux-gnu/libpython3.9.so.1.0)
==34772==    by 0x4932F9D: _PyObject_FastCallDictTstate (in /usr/lib/x86_64-linux-gnu/libpython3.9.so.1.0)
==34772==    by 0x493313F: _PyObject_Call_Prepend (in /usr/lib/x86_64-linux-gnu/libpython3.9.so.1.0)
==34772==    by 0x49996F1: ??? (in /usr/lib/x86_64-linux-gnu/libpython3.9.so.1.0)
==34772==    by 0x498E939: ??? (in /usr/lib/x86_64-linux-gnu/libpython3.9.so.1.0)
==34772==    by 0x493331B: _PyObject_Call (in /usr/lib/x86_64-linux-gnu/libpython3.9.so.1.0)
==34772==
==34772== 1,160 bytes in 2 blocks are possibly lost in loss record 33,825 of 35,156
==34772==    at 0x483877F: malloc (vg_replace_malloc.c:307)
==34772==    by 0x49809C7: ??? (in /usr/lib/x86_64-linux-gnu/libpython3.9.so.1.0)
==34772==    by 0x4A72244: _PyObject_GC_Malloc (in /usr/lib/x86_64-linux-gnu/libpython3.9.so.1.0)
==34772==    by 0x4A72567: _PyObject_GC_NewVar (in /usr/lib/x86_64-linux-gnu/libpython3.9.so.1.0)
==34772==    by 0x48E3750: ??? (in /usr/lib/x86_64-linux-gnu/libpython3.9.so.1.0)
==34772==    by 0x4A0E565: ??? (in /usr/lib/x86_64-linux-gnu/libpython3.9.so.1.0)
==34772==    by 0x492BC7C: _PyFunction_Vectorcall (in /usr/lib/x86_64-linux-gnu/libpython3.9.so.1.0)
==34772==    by 0x4933727: ??? (in /usr/lib/x86_64-linux-gnu/libpython3.9.so.1.0)
==34772==    by 0x48DFC4C: _PyEval_EvalFrameDefault (in /usr/lib/x86_64-linux-gnu/libpython3.9.so.1.0)
==34772==    by 0x4A0EDDB: ??? (in /usr/lib/x86_64-linux-gnu/libpython3.9.so.1.0)
==34772==    by 0x492BC7C: _PyFunction_Vectorcall (in /usr/lib/x86_64-linux-gnu/libpython3.9.so.1.0)
==34772==    by 0x4932F9D: _PyObject_FastCallDictTstate (in /usr/lib/x86_64-linux-gnu/libpython3.9.so.1.0)
==34772==
==34772== 1,208 bytes in 2 blocks are possibly lost in loss record 33,832 of 35,156
==34772==    at 0x483877F: malloc (vg_replace_malloc.c:307)
==34772==    by 0x49809C7: ??? (in /usr/lib/x86_64-linux-gnu/libpython3.9.so.1.0)
==34772==    by 0x4A72244: _PyObject_GC_Malloc (in /usr/lib/x86_64-linux-gnu/libpython3.9.so.1.0)
==34772==    by 0x4A72567: _PyObject_GC_NewVar (in /usr/lib/x86_64-linux-gnu/libpython3.9.so.1.0)
==34772==    by 0x48E3750: ??? (in /usr/lib/x86_64-linux-gnu/libpython3.9.so.1.0)
==34772==    by 0x4A0E565: ??? (in /usr/lib/x86_64-linux-gnu/libpython3.9.so.1.0)
==34772==    by 0x492BC7C: _PyFunction_Vectorcall (in /usr/lib/x86_64-linux-gnu/libpython3.9.so.1.0)
==34772==    by 0x48E0115: _PyEval_EvalFrameDefault (in /usr/lib/x86_64-linux-gnu/libpython3.9.so.1.0)
==34772==    by 0x48D9032: ??? (in /usr/lib/x86_64-linux-gnu/libpython3.9.so.1.0)
==34772==    by 0x48E0115: _PyEval_EvalFrameDefault (in /usr/lib/x86_64-linux-gnu/libpython3.9.so.1.0)
==34772==    by 0x48D9032: ??? (in /usr/lib/x86_64-linux-gnu/libpython3.9.so.1.0)
==34772==    by 0x48E0115: _PyEval_EvalFrameDefault (in /usr/lib/x86_64-linux-gnu/libpython3.9.so.1.0)
==34772==
==34772== 1,216 bytes in 2 blocks are possibly lost in loss record 33,835 of 35,156
==34772==    at 0x483877F: malloc (vg_replace_malloc.c:307)
==34772==    by 0x49809C7: ??? (in /usr/lib/x86_64-linux-gnu/libpython3.9.so.1.0)
==34772==    by 0x4A72244: _PyObject_GC_Malloc (in /usr/lib/x86_64-linux-gnu/libpython3.9.so.1.0)
==34772==    by 0x4A72567: _PyObject_GC_NewVar (in /usr/lib/x86_64-linux-gnu/libpython3.9.so.1.0)
==34772==    by 0x48E3750: ??? (in /usr/lib/x86_64-linux-gnu/libpython3.9.so.1.0)
==34772==    by 0x48D8FF0: ??? (in /usr/lib/x86_64-linux-gnu/libpython3.9.so.1.0)
==34772==    by 0x48E0115: _PyEval_EvalFrameDefault (in /usr/lib/x86_64-linux-gnu/libpython3.9.so.1.0)
==34772==    by 0x48D9032: ??? (in /usr/lib/x86_64-linux-gnu/libpython3.9.so.1.0)
==34772==    by 0x48E0115: _PyEval_EvalFrameDefault (in /usr/lib/x86_64-linux-gnu/libpython3.9.so.1.0)
==34772==    by 0x4A0EDDB: ??? (in /usr/lib/x86_64-linux-gnu/libpython3.9.so.1.0)
==34772==    by 0x492BC7C: _PyFunction_Vectorcall (in /usr/lib/x86_64-linux-gnu/libpython3.9.so.1.0)
==34772==    by 0x48E1584: _PyEval_EvalFrameDefault (in /usr/lib/x86_64-linux-gnu/libpython3.9.so.1.0)
==34772==
==34772== 1,216 bytes in 2 blocks are possibly lost in loss record 33,836 of 35,156
==34772==    at 0x483877F: malloc (vg_replace_malloc.c:307)
==34772==    by 0x49809C7: ??? (in /usr/lib/x86_64-linux-gnu/libpython3.9.so.1.0)
==34772==    by 0x4A72244: _PyObject_GC_Malloc (in /usr/lib/x86_64-linux-gnu/libpython3.9.so.1.0)
==34772==    by 0x4A72567: _PyObject_GC_NewVar (in /usr/lib/x86_64-linux-gnu/libpython3.9.so.1.0)
==34772==    by 0x48E3750: ??? (in /usr/lib/x86_64-linux-gnu/libpython3.9.so.1.0)
==34772==    by 0x4A0E565: ??? (in /usr/lib/x86_64-linux-gnu/libpython3.9.so.1.0)
==34772==    by 0x492BC7C: _PyFunction_Vectorcall (in /usr/lib/x86_64-linux-gnu/libpython3.9.so.1.0)
==34772==    by 0x48DFC4C: _PyEval_EvalFrameDefault (in /usr/lib/x86_64-linux-gnu/libpython3.9.so.1.0)
==34772==    by 0x4A0EDDB: ??? (in /usr/lib/x86_64-linux-gnu/libpython3.9.so.1.0)
==34772==    by 0x492BC7C: _PyFunction_Vectorcall (in /usr/lib/x86_64-linux-gnu/libpython3.9.so.1.0)
==34772==    by 0x48DFC4C: _PyEval_EvalFrameDefault (in /usr/lib/x86_64-linux-gnu/libpython3.9.so.1.0)
==34772==    by 0x4A0EDDB: ??? (in /usr/lib/x86_64-linux-gnu/libpython3.9.so.1.0)
==34772==
==34772== 1,224 bytes in 2 blocks are possibly lost in loss record 33,837 of 35,156
==34772==    at 0x483877F: malloc (vg_replace_malloc.c:307)
==34772==    by 0x49809C7: ??? (in /usr/lib/x86_64-linux-gnu/libpython3.9.so.1.0)
==34772==    by 0x4980ABF: ??? (in /usr/lib/x86_64-linux-gnu/libpython3.9.so.1.0)
==34772==    by 0x4A6E0D4: _PyObject_GC_Resize (in /usr/lib/x86_64-linux-gnu/libpython3.9.so.1.0)
==34772==    by 0x48E3568: ??? (in /usr/lib/x86_64-linux-gnu/libpython3.9.so.1.0)
==34772==    by 0x48D8FF0: ??? (in /usr/lib/x86_64-linux-gnu/libpython3.9.so.1.0)
==34772==    by 0x48E0115: _PyEval_EvalFrameDefault (in /usr/lib/x86_64-linux-gnu/libpython3.9.so.1.0)
==34772==    by 0x48D9032: ??? (in /usr/lib/x86_64-linux-gnu/libpython3.9.so.1.0)
==34772==    by 0x48E0115: _PyEval_EvalFrameDefault (in /usr/lib/x86_64-linux-gnu/libpython3.9.so.1.0)
==34772==    by 0x48D9032: ??? (in /usr/lib/x86_64-linux-gnu/libpython3.9.so.1.0)
==34772==    by 0x48E0115: _PyEval_EvalFrameDefault (in /usr/lib/x86_64-linux-gnu/libpython3.9.so.1.0)
==34772==    by 0x48D9032: ??? (in /usr/lib/x86_64-linux-gnu/libpython3.9.so.1.0)
==34772==
==34772== 1,232 bytes in 2 blocks are possibly lost in loss record 33,839 of 35,156
==34772==    at 0x483877F: malloc (vg_replace_malloc.c:307)
==34772==    by 0x49809C7: ??? (in /usr/lib/x86_64-linux-gnu/libpython3.9.so.1.0)
==34772==    by 0x4A72244: _PyObject_GC_Malloc (in /usr/lib/x86_64-linux-gnu/libpython3.9.so.1.0)
==34772==    by 0x4A72567: _PyObject_GC_NewVar (in /usr/lib/x86_64-linux-gnu/libpython3.9.so.1.0)
==34772==    by 0x48E3750: ??? (in /usr/lib/x86_64-linux-gnu/libpython3.9.so.1.0)
==34772==    by 0x4A0E565: ??? (in /usr/lib/x86_64-linux-gnu/libpython3.9.so.1.0)
==34772==    by 0x492BC7C: _PyFunction_Vectorcall (in /usr/lib/x86_64-linux-gnu/libpython3.9.so.1.0)
==34772==    by 0x4932F22: _PyObject_FastCallDictTstate (in /usr/lib/x86_64-linux-gnu/libpython3.9.so.1.0)
==34772==    by 0x493313F: _PyObject_Call_Prepend (in /usr/lib/x86_64-linux-gnu/libpython3.9.so.1.0)
==34772==    by 0x4998F56: ??? (in /usr/lib/x86_64-linux-gnu/libpython3.9.so.1.0)
==34772==    by 0x498E8F5: ??? (in /usr/lib/x86_64-linux-gnu/libpython3.9.so.1.0)
==34772==    by 0x4930A4F: _PyObject_MakeTpCall (in /usr/lib/x86_64-linux-gnu/libpython3.9.so.1.0)
==34772==
==34772== 1,288 bytes in 2 blocks are possibly lost in loss record 33,901 of 35,156
==34772==    at 0x483AD7B: realloc (vg_replace_malloc.c:834)
==34772==    by 0x4A6E0D4: _PyObject_GC_Resize (in /usr/lib/x86_64-linux-gnu/libpython3.9.so.1.0)
==34772==    by 0x48E3568: ??? (in /usr/lib/x86_64-linux-gnu/libpython3.9.so.1.0)
==34772==    by 0x4A0E565: ??? (in /usr/lib/x86_64-linux-gnu/libpython3.9.so.1.0)
==34772==    by 0x492BC7C: _PyFunction_Vectorcall (in /usr/lib/x86_64-linux-gnu/libpython3.9.so.1.0)
==34772==    by 0x48E1584: _PyEval_EvalFrameDefault (in /usr/lib/x86_64-linux-gnu/libpython3.9.so.1.0)
==34772==    by 0x4A0EDDB: ??? (in /usr/lib/x86_64-linux-gnu/libpython3.9.so.1.0)
==34772==    by 0x4A0F12D: _PyEval_EvalCodeWithName (in /usr/lib/x86_64-linux-gnu/libpython3.9.so.1.0)
==34772==    by 0x4A0F17D: PyEval_EvalCodeEx (in /usr/lib/x86_64-linux-gnu/libpython3.9.so.1.0)
==34772==    by 0x4A0A72A: PyEval_EvalCode (in /usr/lib/x86_64-linux-gnu/libpython3.9.so.1.0)
==34772==    by 0x4A092A0: ??? (in /usr/lib/x86_64-linux-gnu/libpython3.9.so.1.0)
==34772==    by 0x497BE83: ??? (in /usr/lib/x86_64-linux-gnu/libpython3.9.so.1.0)
==34772==
==34772== 1,344 bytes in 2 blocks are possibly lost in loss record 33,914 of 35,156
==34772==    at 0x483877F: malloc (vg_replace_malloc.c:307)
==34772==    by 0x49809C7: ??? (in /usr/lib/x86_64-linux-gnu/libpython3.9.so.1.0)
==34772==    by 0x4A72244: _PyObject_GC_Malloc (in /usr/lib/x86_64-linux-gnu/libpython3.9.so.1.0)
==34772==    by 0x4A72567: _PyObject_GC_NewVar (in /usr/lib/x86_64-linux-gnu/libpython3.9.so.1.0)
==34772==    by 0x48E3750: ??? (in /usr/lib/x86_64-linux-gnu/libpython3.9.so.1.0)
==34772==    by 0x4A0E565: ??? (in /usr/lib/x86_64-linux-gnu/libpython3.9.so.1.0)
==34772==    by 0x492BC7C: _PyFunction_Vectorcall (in /usr/lib/x86_64-linux-gnu/libpython3.9.so.1.0)
==34772==    by 0x48E0115: _PyEval_EvalFrameDefault (in /usr/lib/x86_64-linux-gnu/libpython3.9.so.1.0)
==34772==    by 0x4945C8E: ??? (in /usr/lib/x86_64-linux-gnu/libpython3.9.so.1.0)
==34772==    by 0x48DFBD4: _PyEval_EvalFrameDefault (in /usr/lib/x86_64-linux-gnu/libpython3.9.so.1.0)
==34772==    by 0x4945C8E: ??? (in /usr/lib/x86_64-linux-gnu/libpython3.9.so.1.0)
==34772==    by 0x48DFBD4: _PyEval_EvalFrameDefault (in /usr/lib/x86_64-linux-gnu/libpython3.9.so.1.0)
==34772==
==34772== 1,344 bytes in 2 blocks are possibly lost in loss record 33,915 of 35,156
==34772==    at 0x483AD7B: realloc (vg_replace_malloc.c:834)
==34772==    by 0x4A6E0D4: _PyObject_GC_Resize (in /usr/lib/x86_64-linux-gnu/libpython3.9.so.1.0)
==34772==    by 0x48E3568: ??? (in /usr/lib/x86_64-linux-gnu/libpython3.9.so.1.0)
==34772==    by 0x4A0E565: ??? (in /usr/lib/x86_64-linux-gnu/libpython3.9.so.1.0)
==34772==    by 0x492BC7C: _PyFunction_Vectorcall (in /usr/lib/x86_64-linux-gnu/libpython3.9.so.1.0)
==34772==    by 0x48E0115: _PyEval_EvalFrameDefault (in /usr/lib/x86_64-linux-gnu/libpython3.9.so.1.0)
==34772==    by 0x4945C8E: ??? (in /usr/lib/x86_64-linux-gnu/libpython3.9.so.1.0)
==34772==    by 0x48DFBD4: _PyEval_EvalFrameDefault (in /usr/lib/x86_64-linux-gnu/libpython3.9.so.1.0)
==34772==    by 0x4945C8E: ??? (in /usr/lib/x86_64-linux-gnu/libpython3.9.so.1.0)
==34772==    by 0x48DFBD4: _PyEval_EvalFrameDefault (in /usr/lib/x86_64-linux-gnu/libpython3.9.so.1.0)
==34772==    by 0x4945C8E: ??? (in /usr/lib/x86_64-linux-gnu/libpython3.9.so.1.0)
==34772==    by 0x48DFBD4: _PyEval_EvalFrameDefault (in /usr/lib/x86_64-linux-gnu/libpython3.9.so.1.0)
==34772==
==34772== 1,608 bytes in 3 blocks are possibly lost in loss record 33,998 of 35,156
==34772==    at 0x483877F: malloc (vg_replace_malloc.c:307)
==34772==    by 0x49809C7: ??? (in /usr/lib/x86_64-linux-gnu/libpython3.9.so.1.0)
==34772==    by 0x4A72244: _PyObject_GC_Malloc (in /usr/lib/x86_64-linux-gnu/libpython3.9.so.1.0)
==34772==    by 0x4A72567: _PyObject_GC_NewVar (in /usr/lib/x86_64-linux-gnu/libpython3.9.so.1.0)
==34772==    by 0x48E3750: ??? (in /usr/lib/x86_64-linux-gnu/libpython3.9.so.1.0)
==34772==    by 0x4A0E565: ??? (in /usr/lib/x86_64-linux-gnu/libpython3.9.so.1.0)
==34772==    by 0x492BC7C: _PyFunction_Vectorcall (in /usr/lib/x86_64-linux-gnu/libpython3.9.so.1.0)
==34772==    by 0x4932723: ??? (in /usr/lib/x86_64-linux-gnu/libpython3.9.so.1.0)
==34772==    by 0x4932A8A: _PyObject_CallMethodIdObjArgs (in /usr/lib/x86_64-linux-gnu/libpython3.9.so.1.0)
==34772==    by 0x4A34BDC: PyImport_ImportModuleLevelObject (in /usr/lib/x86_64-linux-gnu/libpython3.9.so.1.0)
==34772==    by 0x48E0AD1: _PyEval_EvalFrameDefault (in /usr/lib/x86_64-linux-gnu/libpython3.9.so.1.0)
==34772==    by 0x4A0EDDB: ??? (in /usr/lib/x86_64-linux-gnu/libpython3.9.so.1.0)
==34772==
==34772== 1,680 bytes in 2 blocks are possibly lost in loss record 34,007 of 35,156
==34772==    at 0x483877F: malloc (vg_replace_malloc.c:307)
==34772==    by 0x49809C7: ??? (in /usr/lib/x86_64-linux-gnu/libpython3.9.so.1.0)
==34772==    by 0x4980ABF: ??? (in /usr/lib/x86_64-linux-gnu/libpython3.9.so.1.0)
==34772==    by 0x4A6E0D4: _PyObject_GC_Resize (in /usr/lib/x86_64-linux-gnu/libpython3.9.so.1.0)
==34772==    by 0x48E3568: ??? (in /usr/lib/x86_64-linux-gnu/libpython3.9.so.1.0)
==34772==    by 0x4A0E565: ??? (in /usr/lib/x86_64-linux-gnu/libpython3.9.so.1.0)
==34772==    by 0x492BC7C: _PyFunction_Vectorcall (in /usr/lib/x86_64-linux-gnu/libpython3.9.so.1.0)
==34772==    by 0x48E0115: _PyEval_EvalFrameDefault (in /usr/lib/x86_64-linux-gnu/libpython3.9.so.1.0)
==34772==    by 0x48D9032: ??? (in /usr/lib/x86_64-linux-gnu/libpython3.9.so.1.0)
==34772==    by 0x48E0115: _PyEval_EvalFrameDefault (in /usr/lib/x86_64-linux-gnu/libpython3.9.so.1.0)
==34772==    by 0x4A0EDDB: ??? (in /usr/lib/x86_64-linux-gnu/libpython3.9.so.1.0)
==34772==    by 0x492BC7C: _PyFunction_Vectorcall (in /usr/lib/x86_64-linux-gnu/libpython3.9.so.1.0)
==34772==
==34772== 1,872 bytes in 3 blocks are possibly lost in loss record 34,045 of 35,156
==34772==    at 0x483877F: malloc (vg_replace_malloc.c:307)
==34772==    by 0x49809C7: ??? (in /usr/lib/x86_64-linux-gnu/libpython3.9.so.1.0)
==34772==    by 0x4A72244: _PyObject_GC_Malloc (in /usr/lib/x86_64-linux-gnu/libpython3.9.so.1.0)
==34772==    by 0x4A72567: _PyObject_GC_NewVar (in /usr/lib/x86_64-linux-gnu/libpython3.9.so.1.0)
==34772==    by 0x4989DC1: PyTuple_New (in /usr/lib/x86_64-linux-gnu/libpython3.9.so.1.0)
==34772==    by 0x4A3F1A7: ??? (in /usr/lib/x86_64-linux-gnu/libpython3.9.so.1.0)
==34772==    by 0x4A3FBCB: ??? (in /usr/lib/x86_64-linux-gnu/libpython3.9.so.1.0)
==34772==    by 0x4A3F1D0: ??? (in /usr/lib/x86_64-linux-gnu/libpython3.9.so.1.0)
==34772==    by 0x4A3FBCB: ??? (in /usr/lib/x86_64-linux-gnu/libpython3.9.so.1.0)
==34772==    by 0x4A3F1D0: ??? (in /usr/lib/x86_64-linux-gnu/libpython3.9.so.1.0)
==34772==    by 0x4A3FBCB: ??? (in /usr/lib/x86_64-linux-gnu/libpython3.9.so.1.0)
==34772==    by 0x4A40C1F: ??? (in /usr/lib/x86_64-linux-gnu/libpython3.9.so.1.0)
==34772==
==34772== 2,080 bytes in 4 blocks are possibly lost in loss record 34,218 of 35,156
==34772==    at 0x483877F: malloc (vg_replace_malloc.c:307)
==34772==    by 0x49809C7: ??? (in /usr/lib/x86_64-linux-gnu/libpython3.9.so.1.0)
==34772==    by 0x4A72244: _PyObject_GC_Malloc (in /usr/lib/x86_64-linux-gnu/libpython3.9.so.1.0)
==34772==    by 0x4A72567: _PyObject_GC_NewVar (in /usr/lib/x86_64-linux-gnu/libpython3.9.so.1.0)
==34772==    by 0x48E3750: ??? (in /usr/lib/x86_64-linux-gnu/libpython3.9.so.1.0)
==34772==    by 0x48D8FF0: ??? (in /usr/lib/x86_64-linux-gnu/libpython3.9.so.1.0)
==34772==    by 0x48E0115: _PyEval_EvalFrameDefault (in /usr/lib/x86_64-linux-gnu/libpython3.9.so.1.0)
==34772==    by 0x48D9032: ??? (in /usr/lib/x86_64-linux-gnu/libpython3.9.so.1.0)
==34772==    by 0x4932723: ??? (in /usr/lib/x86_64-linux-gnu/libpython3.9.so.1.0)
==34772==    by 0x4932A8A: _PyObject_CallMethodIdObjArgs (in /usr/lib/x86_64-linux-gnu/libpython3.9.so.1.0)
==34772==    by 0x4A34D3B: PyImport_ImportModuleLevelObject (in /usr/lib/x86_64-linux-gnu/libpython3.9.so.1.0)
==34772==    by 0x4A0B009: ??? (in /usr/lib/x86_64-linux-gnu/libpython3.9.so.1.0)
==34772==
==34772== 2,312 bytes in 4 blocks are possibly lost in loss record 34,286 of 35,156
==34772==    at 0x483877F: malloc (vg_replace_malloc.c:307)
==34772==    by 0x49809C7: ??? (in /usr/lib/x86_64-linux-gnu/libpython3.9.so.1.0)
==34772==    by 0x4A72244: _PyObject_GC_Malloc (in /usr/lib/x86_64-linux-gnu/libpython3.9.so.1.0)
==34772==    by 0x4A72567: _PyObject_GC_NewVar (in /usr/lib/x86_64-linux-gnu/libpython3.9.so.1.0)
==34772==    by 0x48E3750: ??? (in /usr/lib/x86_64-linux-gnu/libpython3.9.so.1.0)
==34772==    by 0x4A0E565: ??? (in /usr/lib/x86_64-linux-gnu/libpython3.9.so.1.0)
==34772==    by 0x492BC7C: _PyFunction_Vectorcall (in /usr/lib/x86_64-linux-gnu/libpython3.9.so.1.0)
==34772==    by 0x4932F22: _PyObject_FastCallDictTstate (in /usr/lib/x86_64-linux-gnu/libpython3.9.so.1.0)
==34772==    by 0x493313F: _PyObject_Call_Prepend (in /usr/lib/x86_64-linux-gnu/libpython3.9.so.1.0)
==34772==    by 0x49996F1: ??? (in /usr/lib/x86_64-linux-gnu/libpython3.9.so.1.0)
==34772==    by 0x498E939: ??? (in /usr/lib/x86_64-linux-gnu/libpython3.9.so.1.0)
==34772==    by 0x4930A4F: _PyObject_MakeTpCall (in /usr/lib/x86_64-linux-gnu/libpython3.9.so.1.0)
==34772==
==34772== 2,376 bytes in 4 blocks are possibly lost in loss record 34,291 of 35,156
==34772==    at 0x483877F: malloc (vg_replace_malloc.c:307)
==34772==    by 0x49809C7: ??? (in /usr/lib/x86_64-linux-gnu/libpython3.9.so.1.0)
==34772==    by 0x4A72244: _PyObject_GC_Malloc (in /usr/lib/x86_64-linux-gnu/libpython3.9.so.1.0)
==34772==    by 0x4A72567: _PyObject_GC_NewVar (in /usr/lib/x86_64-linux-gnu/libpython3.9.so.1.0)
==34772==    by 0x4989DC1: PyTuple_New (in /usr/lib/x86_64-linux-gnu/libpython3.9.so.1.0)
==34772==    by 0x4A3F1A7: ??? (in /usr/lib/x86_64-linux-gnu/libpython3.9.so.1.0)
==34772==    by 0x4A3FBE1: ??? (in /usr/lib/x86_64-linux-gnu/libpython3.9.so.1.0)
==34772==    by 0x4A3F1D0: ??? (in /usr/lib/x86_64-linux-gnu/libpython3.9.so.1.0)
==34772==    by 0x4A3FBCB: ??? (in /usr/lib/x86_64-linux-gnu/libpython3.9.so.1.0)
==34772==    by 0x4A40C1F: ??? (in /usr/lib/x86_64-linux-gnu/libpython3.9.so.1.0)
==34772==    by 0x497BD32: ??? (in /usr/lib/x86_64-linux-gnu/libpython3.9.so.1.0)
==34772==    by 0x48E1584: _PyEval_EvalFrameDefault (in /usr/lib/x86_64-linux-gnu/libpython3.9.so.1.0)
==34772==
==34772== 2,432 bytes in 4 blocks are possibly lost in loss record 34,297 of 35,156
==34772==    at 0x483877F: malloc (vg_replace_malloc.c:307)
==34772==    by 0x49809C7: ??? (in /usr/lib/x86_64-linux-gnu/libpython3.9.so.1.0)
==34772==    by 0x4980ABF: ??? (in /usr/lib/x86_64-linux-gnu/libpython3.9.so.1.0)
==34772==    by 0x4A6E0D4: _PyObject_GC_Resize (in /usr/lib/x86_64-linux-gnu/libpython3.9.so.1.0)
==34772==    by 0x48E3568: ??? (in /usr/lib/x86_64-linux-gnu/libpython3.9.so.1.0)
==34772==    by 0x48D8FF0: ??? (in /usr/lib/x86_64-linux-gnu/libpython3.9.so.1.0)
==34772==    by 0x48E0115: _PyEval_EvalFrameDefault (in /usr/lib/x86_64-linux-gnu/libpython3.9.so.1.0)
==34772==    by 0x48D9032: ??? (in /usr/lib/x86_64-linux-gnu/libpython3.9.so.1.0)
==34772==    by 0x48E0115: _PyEval_EvalFrameDefault (in /usr/lib/x86_64-linux-gnu/libpython3.9.so.1.0)
==34772==    by 0x48D9032: ??? (in /usr/lib/x86_64-linux-gnu/libpython3.9.so.1.0)
==34772==    by 0x48E0115: _PyEval_EvalFrameDefault (in /usr/lib/x86_64-linux-gnu/libpython3.9.so.1.0)
==34772==    by 0x4A0EDDB: ??? (in /usr/lib/x86_64-linux-gnu/libpython3.9.so.1.0)
==34772==
==34772== 2,680 bytes in 5 blocks are possibly lost in loss record 34,313 of 35,156
==34772==    at 0x483877F: malloc (vg_replace_malloc.c:307)
==34772==    by 0x49809C7: ??? (in /usr/lib/x86_64-linux-gnu/libpython3.9.so.1.0)
==34772==    by 0x4980ABF: ??? (in /usr/lib/x86_64-linux-gnu/libpython3.9.so.1.0)
==34772==    by 0x4A6E0D4: _PyObject_GC_Resize (in /usr/lib/x86_64-linux-gnu/libpython3.9.so.1.0)
==34772==    by 0x48E3568: ??? (in /usr/lib/x86_64-linux-gnu/libpython3.9.so.1.0)
==34772==    by 0x4A0E565: ??? (in /usr/lib/x86_64-linux-gnu/libpython3.9.so.1.0)
==34772==    by 0x492BC7C: _PyFunction_Vectorcall (in /usr/lib/x86_64-linux-gnu/libpython3.9.so.1.0)
==34772==    by 0x4932723: ??? (in /usr/lib/x86_64-linux-gnu/libpython3.9.so.1.0)
==34772==    by 0x4932A8A: _PyObject_CallMethodIdObjArgs (in /usr/lib/x86_64-linux-gnu/libpython3.9.so.1.0)
==34772==    by 0x4A34BDC: PyImport_ImportModuleLevelObject (in /usr/lib/x86_64-linux-gnu/libpython3.9.so.1.0)
==34772==    by 0x48E0AD1: _PyEval_EvalFrameDefault (in /usr/lib/x86_64-linux-gnu/libpython3.9.so.1.0)
==34772==    by 0x4A0EDDB: ??? (in /usr/lib/x86_64-linux-gnu/libpython3.9.so.1.0)
==34772==
==34772== 3,280 bytes in 6 blocks are possibly lost in loss record 34,358 of 35,156
==34772==    at 0x483877F: malloc (vg_replace_malloc.c:307)
==34772==    by 0x49809C7: ??? (in /usr/lib/x86_64-linux-gnu/libpython3.9.so.1.0)
==34772==    by 0x4A72244: _PyObject_GC_Malloc (in /usr/lib/x86_64-linux-gnu/libpython3.9.so.1.0)
==34772==    by 0x4A72567: _PyObject_GC_NewVar (in /usr/lib/x86_64-linux-gnu/libpython3.9.so.1.0)
==34772==    by 0x48E3750: ??? (in /usr/lib/x86_64-linux-gnu/libpython3.9.so.1.0)
==34772==    by 0x48D8FF0: ??? (in /usr/lib/x86_64-linux-gnu/libpython3.9.so.1.0)
==34772==    by 0x48E0115: _PyEval_EvalFrameDefault (in /usr/lib/x86_64-linux-gnu/libpython3.9.so.1.0)
==34772==    by 0x4A0EDDB: ??? (in /usr/lib/x86_64-linux-gnu/libpython3.9.so.1.0)
==34772==    by 0x492BC7C: _PyFunction_Vectorcall (in /usr/lib/x86_64-linux-gnu/libpython3.9.so.1.0)
==34772==    by 0x48E0115: _PyEval_EvalFrameDefault (in /usr/lib/x86_64-linux-gnu/libpython3.9.so.1.0)
==34772==    by 0x48D9032: ??? (in /usr/lib/x86_64-linux-gnu/libpython3.9.so.1.0)
==34772==    by 0x48E0115: _PyEval_EvalFrameDefault (in /usr/lib/x86_64-linux-gnu/libpython3.9.so.1.0)
==34772==
==34772== 3,328 bytes in 5 blocks are possibly lost in loss record 34,362 of 35,156
==34772==    at 0x483877F: malloc (vg_replace_malloc.c:307)
==34772==    by 0x49809C7: ??? (in /usr/lib/x86_64-linux-gnu/libpython3.9.so.1.0)
==34772==    by 0x4980ABF: ??? (in /usr/lib/x86_64-linux-gnu/libpython3.9.so.1.0)
==34772==    by 0x4A6E0D4: _PyObject_GC_Resize (in /usr/lib/x86_64-linux-gnu/libpython3.9.so.1.0)
==34772==    by 0x48E3568: ??? (in /usr/lib/x86_64-linux-gnu/libpython3.9.so.1.0)
==34772==    by 0x4A0E565: ??? (in /usr/lib/x86_64-linux-gnu/libpython3.9.so.1.0)
==34772==    by 0x492BC7C: _PyFunction_Vectorcall (in /usr/lib/x86_64-linux-gnu/libpython3.9.so.1.0)
==34772==    by 0x48E0115: _PyEval_EvalFrameDefault (in /usr/lib/x86_64-linux-gnu/libpython3.9.so.1.0)
==34772==    by 0x4945C8E: ??? (in /usr/lib/x86_64-linux-gnu/libpython3.9.so.1.0)
==34772==    by 0x48DFBD4: _PyEval_EvalFrameDefault (in /usr/lib/x86_64-linux-gnu/libpython3.9.so.1.0)
==34772==    by 0x4945C8E: ??? (in /usr/lib/x86_64-linux-gnu/libpython3.9.so.1.0)
==34772==    by 0x48DFBD4: _PyEval_EvalFrameDefault (in /usr/lib/x86_64-linux-gnu/libpython3.9.so.1.0)
==34772==
==34772== 3,616 bytes in 5 blocks are possibly lost in loss record 34,440 of 35,156
==34772==    at 0x483877F: malloc (vg_replace_malloc.c:307)
==34772==    by 0x49809C7: ??? (in /usr/lib/x86_64-linux-gnu/libpython3.9.so.1.0)
==34772==    by 0x4A72244: _PyObject_GC_Malloc (in /usr/lib/x86_64-linux-gnu/libpython3.9.so.1.0)
==34772==    by 0x4A72567: _PyObject_GC_NewVar (in /usr/lib/x86_64-linux-gnu/libpython3.9.so.1.0)
==34772==    by 0x4989DC1: PyTuple_New (in /usr/lib/x86_64-linux-gnu/libpython3.9.so.1.0)
==34772==    by 0x4A3F1A7: ??? (in /usr/lib/x86_64-linux-gnu/libpython3.9.so.1.0)
==34772==    by 0x4A3FBCB: ??? (in /usr/lib/x86_64-linux-gnu/libpython3.9.so.1.0)
==34772==    by 0x4A40C1F: ??? (in /usr/lib/x86_64-linux-gnu/libpython3.9.so.1.0)
==34772==    by 0x497BD32: ??? (in /usr/lib/x86_64-linux-gnu/libpython3.9.so.1.0)
==34772==    by 0x3369BE: pybind11::detail::simple_collector<(pybind11::return_value_policy)1>::call(_object*) const (cast.h:1465)
==34772==    by 0x13E5D68: pybind11::object pybind11::detail::object_api<pybind11::detail::accessor<pybind11::detail::accessor_policies::str_attr> >::operator()<(pybind11::return_value_policy)1, pybind11::bytes>(pybind11::bytes&&) const (cast.h:1635)
==34772==    by 0x13E55AB: gem5::EmbeddedPython::getCode() const (embedded.cc:88)
==34772==
==34772== 3,760 bytes in 5 blocks are possibly lost in loss record 34,448 of 35,156
==34772==    at 0x483877F: malloc (vg_replace_malloc.c:307)
==34772==    by 0x49809C7: ??? (in /usr/lib/x86_64-linux-gnu/libpython3.9.so.1.0)
==34772==    by 0x4A72244: _PyObject_GC_Malloc (in /usr/lib/x86_64-linux-gnu/libpython3.9.so.1.0)
==34772==    by 0x4A72567: _PyObject_GC_NewVar (in /usr/lib/x86_64-linux-gnu/libpython3.9.so.1.0)
==34772==    by 0x4989DC1: PyTuple_New (in /usr/lib/x86_64-linux-gnu/libpython3.9.so.1.0)
==34772==    by 0x4A3F1A7: ??? (in /usr/lib/x86_64-linux-gnu/libpython3.9.so.1.0)
==34772==    by 0x4A3FBE1: ??? (in /usr/lib/x86_64-linux-gnu/libpython3.9.so.1.0)
==34772==    by 0x4A3F1D0: ??? (in /usr/lib/x86_64-linux-gnu/libpython3.9.so.1.0)
==34772==    by 0x4A3FBCB: ??? (in /usr/lib/x86_64-linux-gnu/libpython3.9.so.1.0)
==34772==    by 0x4A40C1F: ??? (in /usr/lib/x86_64-linux-gnu/libpython3.9.so.1.0)
==34772==    by 0x497BD32: ??? (in /usr/lib/x86_64-linux-gnu/libpython3.9.so.1.0)
==34772==    by 0x3369BE: pybind11::detail::simple_collector<(pybind11::return_value_policy)1>::call(_object*) const (cast.h:1465)
==34772==
==34772== 3,880 bytes in 5 blocks are possibly lost in loss record 34,487 of 35,156
==34772==    at 0x483877F: malloc (vg_replace_malloc.c:307)
==34772==    by 0x49809C7: ??? (in /usr/lib/x86_64-linux-gnu/libpython3.9.so.1.0)
==34772==    by 0x4A72244: _PyObject_GC_Malloc (in /usr/lib/x86_64-linux-gnu/libpython3.9.so.1.0)
==34772==    by 0x4A72567: _PyObject_GC_NewVar (in /usr/lib/x86_64-linux-gnu/libpython3.9.so.1.0)
==34772==    by 0x4989DC1: PyTuple_New (in /usr/lib/x86_64-linux-gnu/libpython3.9.so.1.0)
==34772==    by 0x4A3F1A7: ??? (in /usr/lib/x86_64-linux-gnu/libpython3.9.so.1.0)
==34772==    by 0x4A3FBCB: ??? (in /usr/lib/x86_64-linux-gnu/libpython3.9.so.1.0)
==34772==    by 0x4A3F1D0: ??? (in /usr/lib/x86_64-linux-gnu/libpython3.9.so.1.0)
==34772==    by 0x4A3FBCB: ??? (in /usr/lib/x86_64-linux-gnu/libpython3.9.so.1.0)
==34772==    by 0x4A40C1F: ??? (in /usr/lib/x86_64-linux-gnu/libpython3.9.so.1.0)
==34772==    by 0x497BD32: ??? (in /usr/lib/x86_64-linux-gnu/libpython3.9.so.1.0)
==34772==    by 0x48E1584: _PyEval_EvalFrameDefault (in /usr/lib/x86_64-linux-gnu/libpython3.9.so.1.0)
==34772==
==34772== 4,704 bytes in 7 blocks are possibly lost in loss record 34,558 of 35,156
==34772==    at 0x483AD7B: realloc (vg_replace_malloc.c:834)
==34772==    by 0x4A6E0D4: _PyObject_GC_Resize (in /usr/lib/x86_64-linux-gnu/libpython3.9.so.1.0)
==34772==    by 0x48E3568: ??? (in /usr/lib/x86_64-linux-gnu/libpython3.9.so.1.0)
==34772==    by 0x48D8FF0: ??? (in /usr/lib/x86_64-linux-gnu/libpython3.9.so.1.0)
==34772==    by 0x48E0115: _PyEval_EvalFrameDefault (in /usr/lib/x86_64-linux-gnu/libpython3.9.so.1.0)
==34772==    by 0x48D9032: ??? (in /usr/lib/x86_64-linux-gnu/libpython3.9.so.1.0)
==34772==    by 0x48E0115: _PyEval_EvalFrameDefault (in /usr/lib/x86_64-linux-gnu/libpython3.9.so.1.0)
==34772==    by 0x48D9032: ??? (in /usr/lib/x86_64-linux-gnu/libpython3.9.so.1.0)
==34772==    by 0x48E0115: _PyEval_EvalFrameDefault (in /usr/lib/x86_64-linux-gnu/libpython3.9.so.1.0)
==34772==    by 0x4A0EDDB: ??? (in /usr/lib/x86_64-linux-gnu/libpython3.9.so.1.0)
==34772==    by 0x492BC7C: _PyFunction_Vectorcall (in /usr/lib/x86_64-linux-gnu/libpython3.9.so.1.0)
==34772==    by 0x48E1584: _PyEval_EvalFrameDefault (in /usr/lib/x86_64-linux-gnu/libpython3.9.so.1.0)
==34772==
==34772== 6,152 bytes in 9 blocks are possibly lost in loss record 34,621 of 35,156
==34772==    at 0x483877F: malloc (vg_replace_malloc.c:307)
==34772==    by 0x49809C7: ??? (in /usr/lib/x86_64-linux-gnu/libpython3.9.so.1.0)
==34772==    by 0x4A72244: _PyObject_GC_Malloc (in /usr/lib/x86_64-linux-gnu/libpython3.9.so.1.0)
==34772==    by 0x4A72567: _PyObject_GC_NewVar (in /usr/lib/x86_64-linux-gnu/libpython3.9.so.1.0)
==34772==    by 0x4989DC1: PyTuple_New (in /usr/lib/x86_64-linux-gnu/libpython3.9.so.1.0)
==34772==    by 0x4A3F1A7: ??? (in /usr/lib/x86_64-linux-gnu/libpython3.9.so.1.0)
==34772==    by 0x4A3FBCB: ??? (in /usr/lib/x86_64-linux-gnu/libpython3.9.so.1.0)
==34772==    by 0x4A3F1D0: ??? (in /usr/lib/x86_64-linux-gnu/libpython3.9.so.1.0)
==34772==    by 0x4A3FBCB: ??? (in /usr/lib/x86_64-linux-gnu/libpython3.9.so.1.0)
==34772==    by 0x4A40C1F: ??? (in /usr/lib/x86_64-linux-gnu/libpython3.9.so.1.0)
==34772==    by 0x497BD32: ??? (in /usr/lib/x86_64-linux-gnu/libpython3.9.so.1.0)
==34772==    by 0x3369BE: pybind11::detail::simple_collector<(pybind11::return_value_policy)1>::call(_object*) const (cast.h:1465)
==34772==
==34772== 6,720 bytes in 8 blocks are possibly lost in loss record 34,630 of 35,156
==34772==    at 0x483AD7B: realloc (vg_replace_malloc.c:834)
==34772==    by 0x4A6E0D4: _PyObject_GC_Resize (in /usr/lib/x86_64-linux-gnu/libpython3.9.so.1.0)
==34772==    by 0x48E3568: ??? (in /usr/lib/x86_64-linux-gnu/libpython3.9.so.1.0)
==34772==    by 0x4A0E565: ??? (in /usr/lib/x86_64-linux-gnu/libpython3.9.so.1.0)
==34772==    by 0x492BC7C: _PyFunction_Vectorcall (in /usr/lib/x86_64-linux-gnu/libpython3.9.so.1.0)
==34772==    by 0x48E0115: _PyEval_EvalFrameDefault (in /usr/lib/x86_64-linux-gnu/libpython3.9.so.1.0)
==34772==    by 0x48D9032: ??? (in /usr/lib/x86_64-linux-gnu/libpython3.9.so.1.0)
==34772==    by 0x48E0115: _PyEval_EvalFrameDefault (in /usr/lib/x86_64-linux-gnu/libpython3.9.so.1.0)
==34772==    by 0x4A0EDDB: ??? (in /usr/lib/x86_64-linux-gnu/libpython3.9.so.1.0)
==34772==    by 0x492BC7C: _PyFunction_Vectorcall (in /usr/lib/x86_64-linux-gnu/libpython3.9.so.1.0)
==34772==    by 0x48E0115: _PyEval_EvalFrameDefault (in /usr/lib/x86_64-linux-gnu/libpython3.9.so.1.0)
==34772==    by 0x48D9032: ??? (in /usr/lib/x86_64-linux-gnu/libpython3.9.so.1.0)
==34772==
==34772== 10,400 bytes in 20 blocks are possibly lost in loss record 34,729 of 35,156
==34772==    at 0x483877F: malloc (vg_replace_malloc.c:307)
==34772==    by 0x49809C7: ??? (in /usr/lib/x86_64-linux-gnu/libpython3.9.so.1.0)
==34772==    by 0x4980ABF: ??? (in /usr/lib/x86_64-linux-gnu/libpython3.9.so.1.0)
==34772==    by 0x4A6E0D4: _PyObject_GC_Resize (in /usr/lib/x86_64-linux-gnu/libpython3.9.so.1.0)
==34772==    by 0x48E3568: ??? (in /usr/lib/x86_64-linux-gnu/libpython3.9.so.1.0)
==34772==    by 0x48D8FF0: ??? (in /usr/lib/x86_64-linux-gnu/libpython3.9.so.1.0)
==34772==    by 0x48E0115: _PyEval_EvalFrameDefault (in /usr/lib/x86_64-linux-gnu/libpython3.9.so.1.0)
==34772==    by 0x48D9032: ??? (in /usr/lib/x86_64-linux-gnu/libpython3.9.so.1.0)
==34772==    by 0x4932723: ??? (in /usr/lib/x86_64-linux-gnu/libpython3.9.so.1.0)
==34772==    by 0x4932A8A: _PyObject_CallMethodIdObjArgs (in /usr/lib/x86_64-linux-gnu/libpython3.9.so.1.0)
==34772==    by 0x4A34D3B: PyImport_ImportModuleLevelObject (in /usr/lib/x86_64-linux-gnu/libpython3.9.so.1.0)
==34772==    by 0x48E0AD1: _PyEval_EvalFrameDefault (in /usr/lib/x86_64-linux-gnu/libpython3.9.so.1.0)
==34772==
==34772== 10,920 bytes in 13 blocks are possibly lost in loss record 34,740 of 35,156
==34772==    at 0x483877F: malloc (vg_replace_malloc.c:307)
==34772==    by 0x49809C7: ??? (in /usr/lib/x86_64-linux-gnu/libpython3.9.so.1.0)
==34772==    by 0x4A72244: _PyObject_GC_Malloc (in /usr/lib/x86_64-linux-gnu/libpython3.9.so.1.0)
==34772==    by 0x4A72567: _PyObject_GC_NewVar (in /usr/lib/x86_64-linux-gnu/libpython3.9.so.1.0)
==34772==    by 0x48E3750: ??? (in /usr/lib/x86_64-linux-gnu/libpython3.9.so.1.0)
==34772==    by 0x4A0E565: ??? (in /usr/lib/x86_64-linux-gnu/libpython3.9.so.1.0)
==34772==    by 0x492BC7C: _PyFunction_Vectorcall (in /usr/lib/x86_64-linux-gnu/libpython3.9.so.1.0)
==34772==    by 0x48E0115: _PyEval_EvalFrameDefault (in /usr/lib/x86_64-linux-gnu/libpython3.9.so.1.0)
==34772==    by 0x48D9032: ??? (in /usr/lib/x86_64-linux-gnu/libpython3.9.so.1.0)
==34772==    by 0x48E0115: _PyEval_EvalFrameDefault (in /usr/lib/x86_64-linux-gnu/libpython3.9.so.1.0)
==34772==    by 0x4A0EDDB: ??? (in /usr/lib/x86_64-linux-gnu/libpython3.9.so.1.0)
==34772==    by 0x492BC7C: _PyFunction_Vectorcall (in /usr/lib/x86_64-linux-gnu/libpython3.9.so.1.0)
==34772==
==34772== 16,896 bytes in 32 blocks are possibly lost in loss record 34,838 of 35,156
==34772==    at 0x483877F: malloc (vg_replace_malloc.c:307)
==34772==    by 0x49809C7: ??? (in /usr/lib/x86_64-linux-gnu/libpython3.9.so.1.0)
==34772==    by 0x4980ABF: ??? (in /usr/lib/x86_64-linux-gnu/libpython3.9.so.1.0)
==34772==    by 0x4A6E0D4: _PyObject_GC_Resize (in /usr/lib/x86_64-linux-gnu/libpython3.9.so.1.0)
==34772==    by 0x48E3568: ??? (in /usr/lib/x86_64-linux-gnu/libpython3.9.so.1.0)
==34772==    by 0x48D8FF0: ??? (in /usr/lib/x86_64-linux-gnu/libpython3.9.so.1.0)
==34772==    by 0x498E52E: ??? (in /usr/lib/x86_64-linux-gnu/libpython3.9.so.1.0)
==34772==    by 0x49905C5: ??? (in /usr/lib/x86_64-linux-gnu/libpython3.9.so.1.0)
==34772==    by 0x497AAFE: PyObject_SetAttr (in /usr/lib/x86_64-linux-gnu/libpython3.9.so.1.0)
==34772==    by 0x48DA9DA: _PyEval_EvalFrameDefault (in /usr/lib/x86_64-linux-gnu/libpython3.9.so.1.0)
==34772==    by 0x48D9032: ??? (in /usr/lib/x86_64-linux-gnu/libpython3.9.so.1.0)
==34772==    by 0x4933727: ??? (in /usr/lib/x86_64-linux-gnu/libpython3.9.so.1.0)
==34772==
==34772== 20,176 bytes in 2 blocks are possibly lost in loss record 34,882 of 35,156
==34772==    at 0x483877F: malloc (vg_replace_malloc.c:307)
==34772==    by 0x49809C7: ??? (in /usr/lib/x86_64-linux-gnu/libpython3.9.so.1.0)
==34772==    by 0x4A72244: _PyObject_GC_Malloc (in /usr/lib/x86_64-linux-gnu/libpython3.9.so.1.0)
==34772==    by 0x4A72567: _PyObject_GC_NewVar (in /usr/lib/x86_64-linux-gnu/libpython3.9.so.1.0)
==34772==    by 0x4989DC1: PyTuple_New (in /usr/lib/x86_64-linux-gnu/libpython3.9.so.1.0)
==34772==    by 0x4A3F1A7: ??? (in /usr/lib/x86_64-linux-gnu/libpython3.9.so.1.0)
==34772==    by 0x4A3F1D0: ??? (in /usr/lib/x86_64-linux-gnu/libpython3.9.so.1.0)
==34772==    by 0x4A3FBCB: ??? (in /usr/lib/x86_64-linux-gnu/libpython3.9.so.1.0)
==34772==    by 0x4A3F1D0: ??? (in /usr/lib/x86_64-linux-gnu/libpython3.9.so.1.0)
==34772==    by 0x4A3FBCB: ??? (in /usr/lib/x86_64-linux-gnu/libpython3.9.so.1.0)
==34772==    by 0x4A40C1F: ??? (in /usr/lib/x86_64-linux-gnu/libpython3.9.so.1.0)
==34772==    by 0x497BD32: ??? (in /usr/lib/x86_64-linux-gnu/libpython3.9.so.1.0)
==34772==
==34772== 21,520 bytes in 40 blocks are possibly lost in loss record 34,891 of 35,156
==34772==    at 0x483877F: malloc (vg_replace_malloc.c:307)
==34772==    by 0x49809C7: ??? (in /usr/lib/x86_64-linux-gnu/libpython3.9.so.1.0)
==34772==    by 0x4980ABF: ??? (in /usr/lib/x86_64-linux-gnu/libpython3.9.so.1.0)
==34772==    by 0x4A6E0D4: _PyObject_GC_Resize (in /usr/lib/x86_64-linux-gnu/libpython3.9.so.1.0)
==34772==    by 0x48E3568: ??? (in /usr/lib/x86_64-linux-gnu/libpython3.9.so.1.0)
==34772==    by 0x48D8FF0: ??? (in /usr/lib/x86_64-linux-gnu/libpython3.9.so.1.0)
==34772==    by 0x4933727: ??? (in /usr/lib/x86_64-linux-gnu/libpython3.9.so.1.0)
==34772==    by 0x48E1584: _PyEval_EvalFrameDefault (in /usr/lib/x86_64-linux-gnu/libpython3.9.so.1.0)
==34772==    by 0x48D9032: ??? (in /usr/lib/x86_64-linux-gnu/libpython3.9.so.1.0)
==34772==    by 0x4933727: ??? (in /usr/lib/x86_64-linux-gnu/libpython3.9.so.1.0)
==34772==    by 0x48E1584: _PyEval_EvalFrameDefault (in /usr/lib/x86_64-linux-gnu/libpython3.9.so.1.0)
==34772==    by 0x48D9032: ??? (in /usr/lib/x86_64-linux-gnu/libpython3.9.so.1.0)
==34772==
==34772== 22,360 bytes in 43 blocks are possibly lost in loss record 34,892 of 35,156
==34772==    at 0x483877F: malloc (vg_replace_malloc.c:307)
==34772==    by 0x49809C7: ??? (in /usr/lib/x86_64-linux-gnu/libpython3.9.so.1.0)
==34772==    by 0x4A72244: _PyObject_GC_Malloc (in /usr/lib/x86_64-linux-gnu/libpython3.9.so.1.0)
==34772==    by 0x4A72567: _PyObject_GC_NewVar (in /usr/lib/x86_64-linux-gnu/libpython3.9.so.1.0)
==34772==    by 0x48E3750: ??? (in /usr/lib/x86_64-linux-gnu/libpython3.9.so.1.0)
==34772==    by 0x48D8FF0: ??? (in /usr/lib/x86_64-linux-gnu/libpython3.9.so.1.0)
==34772==    by 0x48E0115: _PyEval_EvalFrameDefault (in /usr/lib/x86_64-linux-gnu/libpython3.9.so.1.0)
==34772==    by 0x48D9032: ??? (in /usr/lib/x86_64-linux-gnu/libpython3.9.so.1.0)
==34772==    by 0x4932723: ??? (in /usr/lib/x86_64-linux-gnu/libpython3.9.so.1.0)
==34772==    by 0x4932A8A: _PyObject_CallMethodIdObjArgs (in /usr/lib/x86_64-linux-gnu/libpython3.9.so.1.0)
==34772==    by 0x4A34D3B: PyImport_ImportModuleLevelObject (in /usr/lib/x86_64-linux-gnu/libpython3.9.so.1.0)
==34772==    by 0x48E0AD1: _PyEval_EvalFrameDefault (in /usr/lib/x86_64-linux-gnu/libpython3.9.so.1.0)
==34772==
==34772== LEAK SUMMARY:
==34772==    definitely lost: 640 bytes in 16 blocks
==34772==    indirectly lost: 0 bytes in 0 blocks
==34772==      possibly lost: 210,160 bytes in 321 blocks
==34772==    still reachable: 246,108,949 bytes in 3,151,566 blocks
==34772==                       of which reachable via heuristic:
==34772==                         newarray           : 151,640 bytes in 11 blocks
==34772==         suppressed: 0 bytes in 0 blocks
==34772== Reachable blocks (those to which a pointer was found) are not shown.
==34772== To see them, rerun with: --leak-check=full --show-leak-kinds=all
==34772==
==34772== For lists of detected and suppressed errors, rerun with: -s
==34772== ERROR SUMMARY: 103 errors from 103 contexts (suppressed: 49103 from 288)
Segmentation fault
